Workbook

Sheet Claude Log
A1: Turn # | B1: Date | C1: User Request | D1: Action Taken | E1: Details | F1: Outcome
A2: 1 | B2: 46143 | C2: シート「5 7 (2)」のL列にある計算式をすべてK列へ移動してほしい | D2: L列の計算式をK列へコピーし、L列をクリア | E2: L列（行6, 8〜17, 20〜23, 25, 27〜32, 34〜36, 43）の運賃計算式をK列の対応行へ移動。L3の「距離」ヘッダーテキストもクリア。K3（特記事項）・K50・K52・K55の既存データは保持。 | F2: K列に全計算式を移動完了。L列はクリア済み。
A3: 4 | B3: 46143 | C3: K5:K47に運賃計算式を挿入（L列に距離入力→K列に運賃反映） | D3: K5:K47の全データ行に運賃計算式を挿入。H列の「202＊2」形式からVALUE(LEFT(...))で番号を抽出するロジック込み | E3: 計算式はLET+VLOOKUP構造。H列番号→運賃マスターA22:B39で車種特定→L列距離で各車種テーブル参照。動作確認：d=15でK39=8500円を確認。注意：各テーブルの最小距離は10kmのため、6km等の小さい値は#N/A→空になる | F3: 37行に計算式挿入完了。L列10km以上の距離入力でK列に運賃が反映される状態を確認済み
A4: 5 | B4: 46143 | C4: L列に距離を入力しても運賃が表示されない問題の修正 | D4: K列の計算式を改良：距離が運賃マスターの最小値未満でもテーブル最小行の運賃を返すよう修正 | E4: VLOOKUPを各車種でIFERROR(VLOOKUP(...),最小行運賃)に変更。3t最小=B5、3t=F5、1t=J5、軽=N5、3tPG=R5を返す。L24・L25にもテスト書き込みで反映を確認 | F4: L5=6→K5=15,000円（3t最小運賃）、L24=6/L25=6→K24・K25=15,000円。L列入力でK列に運賃が反映される状態を確認
A5: 6 | B5: 46143 | C5: シート「5 7」のK列運賃計算式を修正 | D5: K5:K23に最新の運賃計算式を適用 | E5: 既存式の誤り3点を修正：(1)G列参照→H列参照、(2)H列の「10＊2」形式から番号自動抽出（IFERRORでテキスト/数値両対応）、(3)距離が最小値未満時にテーブル最小行運賃を返す改良版IFERROR、(4)最終フォールバック0→空文字 | F5: L10=6,L11=6→K10・K11=5,000円（軽の最小運賃）を確認。L列に距離入力でK列に運賃が反映される状態
A6: 7 | B6: 46143 | C6: 5月の他のシートの運賃計算式チェックと一括修正 | D6: 5月の全日付シート52枚のK5:K47に最新運賃計算式を一括適用 | E6: 監査結果：G参照(誤)が22シート、H+M参照(旧)が18シート、H+L参照(部分的)が6シート、その他5シートで問題あり。手動計算モードで一括書き込みし、最新計算式（H列番号自動抽出+L列距離参照+最小値未満時テーブル最小行運賃返却）を全52シートに適用。サンプル5シート（5 2、5 15、5 22、5 31、5 19(2)）で計算式正常を確認 | F6: 5月の全日付シートで統一運賃計算式が稼働。L列に距離を入力するとK列に運賃が反映される状態
A7: 8 | B7: 46143 | C7: 「5 1 」シートのH4:H21を車番毎にまとめる | D7: 現在の順番を維持したまま車番グループ（10→12→13）にまとめてA5:R14に並び替え、A列番号を1〜10に振り直し | E7: 初出順：10（1位）→12（2位）→13（3位）。グループ内は元の行順を維持。空行は除去してデータを詰めた。K列運賃計算式は全10行で維持済み | F7: 5 1 !A5:H14で並び替え完了。10グループ(行5-8)、12グループ(行9-12)、13グループ(行13-14)
A8: 9 | B8: 46143 | C8: 「宵」セルを赤文字・黄色背景に書式変更 | D8: 5月全シートのG列で「宵」を含むセルを検索し、赤文字(#FF0000)・黄色背景(#FFFF00)を一括適用 | E8: 対象21セル：5 1 (1)、5 1 (2)(2)、5 2(1)、5 2(2)(6)、5 7(2)(3)、5 8(1)、5 8(2)(4)、5 11(2)(1)、5 12(2)(2) | F8: 21セル全てに書式適用完了
A9: 10 | B9: 46143 | C9: 「5 1 」シートの運賃計算式チェック・修正 | D9: J5:J14の運賃計算式をI列削除・行並び替えによるズレ・#REF!から全て修正 | E9: 問題：(1)I列削除でJ8・J12が#REF!、(2)行並び替え後も古い行番号を参照（J7→H14、J9→H7等）。修正：J5:J14を各行自身のH列(号車)とK列(距離)を参照する計算式に書き直し。全10行でrefCorrect=trueを確認 | F9: J5:J14の計算式修正完了。K列に距離入力でJ列に正しく運賃が反映される状態
A10: 11 | B10: 46143 | C10: 「5 1 (2)」シートを車番毎に並び替え | D10: H列の初出順(303→101→202→505→333→666→777→888→7651→7657→7732)でグループ化、各グループ内は台数昇順(1台→＊2→＊3→＊4)に整列。A列番号1-31振り直し、K列計算式も修正 | E10: 31行のデータを行5-35に配置。K5:K35の運賃計算式も各行のH・L列を正しく参照するよう再設定 | F10: 5 1 (2)!H5:H35で正しい車番グループ順を確認。K列計算式refCorrect=true確認
A11: 12 | B11: 46143 | C11: 「5 1 (2)」K列運賃計算式の修正 | D11: K6(手動入力6000→計算式に戻す)とK29(行挿入で計算式なし→追加)を修正 | E11: 列構造確認：J=距離、K=特記事項兼運賃、L=距離(入力列)。K列はL列を参照する計算式。K5=L5(42km)→22,000円(3t)で動作確認 | F11: K6・K29の計算式修正完了。5 1 (2)はL列に距離入力でK列に運賃反映される状態
A12: 13 | B12: 46143 | C12: 運賃計算式のVLOOKUP近似一致バグを修正（5 1 (2)） | D12: VLOOKUP(距離, 上限テーブル, TRUE)→INDEX/MATCH(距離列>=d, 0)に変更。距離テーブルが「上限km」設計のため近似一致では誤った行を参照していた | E12: 旧：VLOOKUP(42,テーブル,TRUE)→40km行=22,000円(誤)。新：MATCH(1,(距離列>=42),0)→50km行=25,000円(正)。5 1 (2) K5:K35全行修正。他シートにも同じ問題あり | F12: K5(303/3t/42km)=25,000円、K10(42km)=25,000円を確認。ユーザーに全シート一括修正を提案
A13: 2 | B13: 46149 | C13: 「5 7 (2)」シートのA6:A52の連番計算を修正してほしい | D13: A49・A51・A52の数式参照ズレを修正 | E13: 各行の数式はIF(B{n}="","",COUNTA($B$4:B{n-2}))が正しいパターン。A49のB49→B47、A51のB51→B49、A52のB52→B50にそれぞれ修正。行挿入/削除による参照ズレが原因。 | F13: A49=41、A51=42、A52=42。数式パターン統一完了。番号重複はB列空行に起因する正常動作。
... A17: 16 | B17: 46153 | C17: 全シートのI列の文字色・太さを5 12シートに合わせてほしい。 | D17: 全55シート（(2)23枚＋非(2)32枚）のXLOOKUP数式セルのフォントを太字・#0000FFに統一。 | E17: 基準：5 12 (2)のI5:I14（bold, #0000FF）。(2)シートはI5:I15範囲、非(2)はシートごとの対象行を個別適用。 | F17: 完了。確認済み：5 12(I9)・5 3(I6)・5 20(2)(I5)・5 31(I5)すべてbold/#0000FF。

Sheet 日付変更シート
A1: 44470

Sheet 6月軽
B2: 6月 軽カーゴ予定表 | D2: NO.１
B3: 荷主 | C3: 種類 | D3: 積込地 | E3: 積降地 | F3: ユーザー名(搬入/搬出) | G3: 時間 | H3: 号車 | I3: 距離 | J3: 特記事項 | K3: 距離 | L3: 終了地 | M3: 予定時間 | N3: 必要時間 | O3: 件数 | P3: メモ
A4: 1
A5: 3 | H5: 2
A6: 4 | H6: 8
A7: 5 | H7: 9
A8: 6 | H8: 11
A9: 7 | H9: 12 | I9: =IFERROR(_xlfn.XLOOKUP(H9,案件・ドライバー一覧!$L$3:$L$17,案件・ドライバー一覧!$M$3:$M$17,""),"")
A10: 8 | H10: 13 | I10: =IFERROR(_xlfn.XLOOKUP(H10,案件・ドライバー一覧!$L$3:$L$17,案件・ドライバー一覧!$M$3:$M$17,""),"")
A11: 9 | H11: 14
A12: 10
A13: 11 | H13: 2＊2
A14: 12 | H14: 8＊2
A15: 13 | H15: 9＊2
A16: 14 | H16: 11＊2
A17: 15 | H17: 12＊2
A18: 16 | H18: 13＊2
A19: 17 | H19: 14＊2
A20: 18
A21: 19 | H21: 2＊3
A22: 20 | H22: 8＊3
A23: 21 | H23: 9＊3
A24: 22 | H24: 11＊3
A25: 23 | H25: 12＊3
A26: 24 | H26: 13＊3
A27: 25 | H27: 14＊3
A28: 26
A29: 27
A30: 28
A31: 29
A32: 30
D35: 現在待機場所 | E35: 待機予定場所 | H35: 目標距離 | J35: 550
B36: 2(255) | C36: 山岸
B37: 8(254) | C37: 砂川 | H37: 残距離 | J37: =550-SUM(K3:K32)-SUM(#REF!)
B38: 9(256) | C38: 前川
B39: 10(257)
B40: 11(258) | C40: 郡司 | H40: 依頼件数 | J40: =SUM(O3:O32)+SUM(SUM(#REF!))
B41: 12(736)
B42: 13(737)
C44: 合計額/380 | D44: =SUM(G44) | F44: 売り上げ額 | G44: =SUM(SUM(J4:J32))+SUM(#REF!)
...

Sheet 6月大型
B1: 11月1日(金) | D1: NO.１
B2: 6月 大型予定表 | C2: 種類 | D2: 積込地 | E2: 積降地 | F2: ユーザー名(搬入/搬出) | G2: 時間 | H2: 号車 | J2: 距離 | K2: 特記事項 | L2: 距離 | M2: 終了地 | N2: 予定時間 | O2: 必要時間 | P2: 件数 | Q2: メモ
A3: =IF(B3="","",COUNTA($B$3:B3))
A4: =IF(B4="","",COUNTA($B$3:B4)) | H4: 303 | I4: 金
A5: =IF(B5="","",COUNTA($B$3:B5)) | H5: 101 | I5: 藤
A6: =IF(B6="","",COUNTA($B$3:B6)) | H6: 202 | I6: 山原
A7: =IF(B7="","",COUNTA($B$3:B7)) | H7: 505 | I7: 辻
A8: =IF(B8="","",COUNTA($B$3:B8)) | H8: 333 | I8: 多
A9: =IF(B9="","",COUNTA($B$3:B9)) | H9: 666 | I9: 森
A10: =IF(B10="","",COUNTA($B$3:B10)) | H10: 777 | I10: 郡
A11: =IF(B11="","",COUNTA($B$3:B11)) | H11: 888 | I11: 平
A12: =IF(B12="","",COUNTA($B$3:B12)) | H12: 7651 | I12: 坂
A13: =IF(B13="","",COUNTA($B$3:B13)) | H13: 7657 | I13: 砂
A14: =IF(B14="","",COUNTA($B$3:B14)) | H14: 7732 | I14: 山岸
A15: =IF(B15="","",COUNTA($B$3:B15))
A16: =IF(B16="","",COUNTA($B$3:B16)) | H16: 303＊2
A17: =IF(B17="","",COUNTA($B$3:B17)) | H17: 101＊2
A18: =IF(B18="","",COUNTA($B$3:B18)) | H18: 202＊2
A19: =IF(B19="","",COUNTA($B$3:B19)) | H19: 505＊2
A20: =IF(B20="","",COUNTA($B$3:B20)) | H20: 333＊2
A21: =IF(B21="","",COUNTA($B$3:B21)) | H21: 666＊2
A22: =IF(B22="","",COUNTA($B$3:B22)) | H22: 777＊2
A23: =IF(B23="","",COUNTA($B$3:B23)) | H23: 888＊2
A24: =IF(B24="","",COUNTA($B$3:B24)) | H24: 7651＊2
A25: =IF(B25="","",COUNTA($B$3:B25)) | H25: 7657＊2
A26: =IF(B26="","",COUNTA($B$3:B26)) | H26: 7732＊2
A27: =IF(B27="","",COUNTA($B$3:B27))
A28: =IF(B28="","",COUNTA($B$3:B28)) | H28: 303＊3
A29: =IF(B29="","",COUNTA($B$3:B29)) | H29: 101＊3
A30: =IF(B30="","",COUNTA($B$3:B30)) | H30: 202＊3
A31: =IF(B31="","",COUNTA($B$3:B31)) | H31: 505＊3
A32: =IF(B32="","",COUNTA($B$3:B32)) | H32: 333＊3
A33: =IF(B33="","",COUNTA($B$3:B33)) | H33: 666＊3
A34: =IF(B34="","",COUNTA($B$3:B34)) | H34: 888＊3
A35: =IF(B35="","",COUNTA($B$3:B35)) | H35: 777＊3
A36: =IF(B36="","",COUNTA($B$3:B36)) | H36: 7651＊3
A37: =IF(B37="","",COUNTA($B$3:B37)) | H37: 7657＊3
A38: =IF(B38="","",COUNTA($B$3:B38)) | H38: 7732＊3
A39: =IF(B39="","",COUNTA($B$3:B39))
A40: =IF(B40="","",COUNTA($B$3:B40))
...

Sheet 6 1 
B2: 46174 | D2: NO.１
B3: 荷主 | C3: 種類 | D3: 積込地 | E3: 積降地 | F3: ユーザー名(搬入/搬出) | G3: 時間 | H3: 号車 | J3: 特記事項 | K3: 距離 | L3: 終了地 | M3: 予定時間 | N3: 必要時間 | O3: 件数 | P3: メモ
A5: =IF(B5="","",COUNTA($B$5:B5)) | I5: =IFERROR(_xlfn.XLOOKUP(H5,案件・ドライバー一覧!$L$3:$L$17,案件・ドライバー一覧!$M$3:$M$17,""),"") | J5: =IF(OR(H5="",K5=""),"",IFERROR(_xlfn.LET(_xlpm.vt,VLOOKUP(IFERROR(VALUE(LEFT(H5,FIND("＊",H5&"＊")-1)),H5),運賃マスター!$A$22:$B$40,2,FALSE),_xlpm.d,K5,IF(_xlpm.vt="2t",IF(_xlpm.d<=100,IFERROR(VLOOKUP(_xlpm.d,運賃マスター!$A$5:$B$14,2,TRUE),運賃マスター!$B$5),運賃マスター!$B$17+CEILING((_xlpm.d-100)/10,1)*運賃マスター!$B$16),IF(_xlpm.vt="3t",IF(_xlpm.d<=100,IFERROR(VLOOKUP(_xlpm.d,運賃マスター!$E$5:$F$14,2,TRUE),運賃マスター!$F$5),運賃マスター!$F$17+CEILING((_xlpm.d-100)/10,1)*運賃マスター!$F$16),IF(_xlpm.vt="1t",IF(_xlpm.d<=100,IFERROR(VLOOKUP(_xlpm.d,運賃マスター!$I$5:$J$14,2,TRUE),運賃マスター!$J$5),運賃マスター!$J$17+CEILING((_xlpm.d-100)/10,1)*運賃マスター!$J$16),IF(_xlpm.vt="軽",IF(_xlpm.d<=50,IFERROR(VLOOKUP(_xlpm.d,運賃マスター!$M$5:$N$14,2,TRUE),運賃マスター!$N$5),IF(_xlpm.d<=100,運賃マスター!$N$15+(_xlpm.d-50)*運賃マスター!$N$16,運賃マスター!$N$17+(_xlpm.d-100)*運賃マスター!$N$18)),IF(_xlpm.vt="3tPG",IF(_xlpm.d<=100,IFERROR(VLOOKUP(_xlpm.d,運賃マスター!$Q$5:$R$14,2,TRUE),運賃マスター!$R$5),運賃マスター!$R$17+CEILING((_xlpm.d-100)/10,1)*運賃マスター!$R$16),"")))))),""))
A6: =IF(B6="","",COUNTA($B$5:B6))
A7: =IF(B7="","",COUNTA($B$5:B7))
A8: =IF(B8="","",COUNTA($B$5:B8))
A9: =IF(B9="","",COUNTA($B$5:B9)) | I9: =IFERROR(_xlfn.XLOOKUP(H9,案件・ドライバー一覧!$L$3:$L$17,案件・ドライバー一覧!$M$3:$M$17,""),"")
A10: =IF(B10="","",COUNTA($B$5:B10))
A11: =IF(B11="","",COUNTA($B$5:B11)) | J11: =IF(OR(H11="",K11=""),"",IFERROR(_xlfn.LET(_xlpm.vt,VLOOKUP(IFERROR(VALUE(LEFT(H11,FIND("＊",H11&"＊")-1)),H11),運賃マスター!$A$22:$B$40,2,FALSE),_xlpm.d,K11,IF(_xlpm.vt="2t",IF(_xlpm.d<=100,IFERROR(VLOOKUP(_xlpm.d,運賃マスター!$A$5:$B$14,2,TRUE),運賃マスター!$B$5),運賃マスター!$B$17+CEILING((_xlpm.d-100)/10,1)*運賃マスター!$B$16),IF(_xlpm.vt="3t",IF(_xlpm.d<=100,IFERROR(VLOOKUP(_xlpm.d,運賃マスター!$E$5:$F$14,2,TRUE),運賃マスター!$F$5),運賃マスター!$F$17+CEILING((_xlpm.d-100)/10,1)*運賃マスター!$F$16),IF(_xlpm.vt="1t",IF(_xlpm.d<=100,IFERROR(VLOOKUP(_xlpm.d,運賃マスター!$I$5:$J$14,2,TRUE),運賃マスター!$J$5),運賃マスター!$J$17+CEILING((_xlpm.d-100)/10,1)*運賃マスター!$J$16),IF(_xlpm.vt="軽",IF(_xlpm.d<=50,IFERROR(VLOOKUP(_xlpm.d,運賃マスター!$M$5:$N$14,2,TRUE),運賃マスター!$N$5),IF(_xlpm.d<=100,運賃マスター!$N$15+(_xlpm.d-50)*運賃マスター!$N$16,運賃マスター!$N$17+(_xlpm.d-100)*運賃マスター!$N$18)),IF(_xlpm.vt="3tPG",IF(_xlpm.d<=100,IFERROR(VLOOKUP(_xlpm.d,運賃マスター!$Q$5:$R$14,2,TRUE),運賃マスター!$R$5),運賃マスター!$R$17+CEILING((_xlpm.d-100)/10,1)*運賃マスター!$R$16),"")))))),""))
A12: =IF(B12="","",COUNTA($B$5:B12))
A13: =IF(B13="","",COUNTA($B$5:B13)) | I13: =IFERROR(_xlfn.XLOOKUP(H13,案件・ドライバー一覧!$L$3:$L$17,案件・ドライバー一覧!$M$3:$M$17,""),"")
A14: =IF(B14="","",COUNTA($B$5:B14))
A15: =IF(B15="","",COUNTA($B$5:B15)) | J15: =IF(OR(H15="",K15=""),"",IFERROR(_xlfn.LET(_xlpm.vt,VLOOKUP(IFERROR(VALUE(LEFT(H15,FIND("＊",H15&"＊")-1)),H15),運賃マスター!$A$22:$B$40,2,FALSE),_xlpm.d,K15,IF(_xlpm.vt="2t",IF(_xlpm.d<=100,IFERROR(VLOOKUP(_xlpm.d,運賃マスター!$A$5:$B$14,2,TRUE),運賃マスター!$B$5),運賃マスター!$B$17+CEILING((_xlpm.d-100)/10,1)*運賃マスター!$B$16),IF(_xlpm.vt="3t",IF(_xlpm.d<=100,IFERROR(VLOOKUP(_xlpm.d,運賃マスター!$E$5:$F$14,2,TRUE),運賃マスター!$F$5),運賃マスター!$F$17+CEILING((_xlpm.d-100)/10,1)*運賃マスター!$F$16),IF(_xlpm.vt="1t",IF(_xlpm.d<=100,IFERROR(VLOOKUP(_xlpm.d,運賃マスター!$I$5:$J$14,2,TRUE),運賃マスター!$J$5),運賃マスター!$J$17+CEILING((_xlpm.d-100)/10,1)*運賃マスター!$J$16),IF(_xlpm.vt="軽",IF(_xlpm.d<=50,IFERROR(VLOOKUP(_xlpm.d,運賃マスター!$M$5:$N$14,2,TRUE),運賃マスター!$N$5),IF(_xlpm.d<=100,運賃マスター!$N$15+(_xlpm.d-50)*運賃マスター!$N$16,運賃マスター!$N$17+(_xlpm.d-100)*運賃マスター!$N$18)),IF(_xlpm.vt="3tPG",IF(_xlpm.d<=100,IFERROR(VLOOKUP(_xlpm.d,運賃マスター!$Q$5:$R$14,2,TRUE),運賃マスター!$R$5),運賃マスター!$R$17+CEILING((_xlpm.d-100)/10,1)*運賃マスター!$R$16),"")))))),""))
A16: =IF(B16="","",COUNTA($B$5:B16)) | J16: =IF(OR(H16="",K16=""),"",IFERROR(_xlfn.LET(_xlpm.vt,VLOOKUP(IFERROR(VALUE(LEFT(H16,FIND("＊",H16&"＊")-1)),H16),運賃マスター!$A$22:$B$40,2,FALSE),_xlpm.d,K16,IF(_xlpm.vt="2t",IF(_xlpm.d<=100,IFERROR(VLOOKUP(_xlpm.d,運賃マスター!$A$5:$B$14,2,TRUE),運賃マスター!$B$5),運賃マスター!$B$17+CEILING((_xlpm.d-100)/10,1)*運賃マスター!$B$16),IF(_xlpm.vt="3t",IF(_xlpm.d<=100,IFERROR(VLOOKUP(_xlpm.d,運賃マスター!$E$5:$F$14,2,TRUE),運賃マスター!$F$5),運賃マスター!$F$17+CEILING((_xlpm.d-100)/10,1)*運賃マスター!$F$16),IF(_xlpm.vt="1t",IF(_xlpm.d<=100,IFERROR(VLOOKUP(_xlpm.d,運賃マスター!$I$5:$J$14,2,TRUE),運賃マスター!$J$5),運賃マスター!$J$17+CEILING((_xlpm.d-100)/10,1)*運賃マスター!$J$16),IF(_xlpm.vt="軽",IF(_xlpm.d<=50,IFERROR(VLOOKUP(_xlpm.d,運賃マスター!$M$5:$N$14,2,TRUE),運賃マスター!$N$5),IF(_xlpm.d<=100,運賃マスター!$N$15+(_xlpm.d-50)*運賃マスター!$N$16,運賃マスター!$N$17+(_xlpm.d-100)*運賃マスター!$N$18)),IF(_xlpm.vt="3tPG",IF(_xlpm.d<=100,IFERROR(VLOOKUP(_xlpm.d,運賃マスター!$Q$5:$R$14,2,TRUE),運賃マスター!$R$5),運賃マスター!$R$17+CEILING((_xlpm.d-100)/10,1)*運賃マスター!$R$16),"")))))),""))
J17: =IF(OR(H17="",K17=""),"",IFERROR(_xlfn.LET(_xlpm.vt,VLOOKUP(IFERROR(VALUE(LEFT(H17,FIND("＊",H17&"＊")-1)),H17),運賃マスター!$A$22:$B$40,2,FALSE),_xlpm.d,K17,IF(_xlpm.vt="2t",IF(_xlpm.d<=100,IFERROR(VLOOKUP(_xlpm.d,運賃マスター!$A$5:$B$14,2,TRUE),運賃マスター!$B$5),運賃マスター!$B$17+CEILING((_xlpm.d-100)/10,1)*運賃マスター!$B$16),IF(_xlpm.vt="3t",IF(_xlpm.d<=100,IFERROR(VLOOKUP(_xlpm.d,運賃マスター!$E$5:$F$14,2,TRUE),運賃マスター!$F$5),運賃マスター!$F$17+CEILING((_xlpm.d-100)/10,1)*運賃マスター!$F$16),IF(_xlpm.vt="1t",IF(_xlpm.d<=100,IFERROR(VLOOKUP(_xlpm.d,運賃マスター!$I$5:$J$14,2,TRUE),運賃マスター!$J$5),運賃マスター!$J$17+CEILING((_xlpm.d-100)/10,1)*運賃マスター!$J$16),IF(_xlpm.vt="軽",IF(_xlpm.d<=50,IFERROR(VLOOKUP(_xlpm.d,運賃マスター!$M$5:$N$14,2,TRUE),運賃マスター!$N$5),IF(_xlpm.d<=100,運賃マスター!$N$15+(_xlpm.d-50)*運賃マスター!$N$16,運賃マスター!$N$17+(_xlpm.d-100)*運賃マスター!$N$18)),IF(_xlpm.vt="3tPG",IF(_xlpm.d<=100,IFERROR(VLOOKUP(_xlpm.d,運賃マスター!$Q$5:$R$14,2,TRUE),運賃マスター!$R$5),運賃マスター!$R$17+CEILING((_xlpm.d-100)/10,1)*運賃マスター!$R$16),"")))))),""))
J18: =IF(OR(H18="",K18=""),"",IFERROR(_xlfn.LET(_xlpm.vt,VLOOKUP(IFERROR(VALUE(LEFT(H18,FIND("＊",H18&"＊")-1)),H18),運賃マスター!$A$22:$B$40,2,FALSE),_xlpm.d,K18,IF(_xlpm.vt="2t",IF(_xlpm.d<=100,IFERROR(VLOOKUP(_xlpm.d,運賃マスター!$A$5:$B$14,2,TRUE),運賃マスター!$B$5),運賃マスター!$B$17+CEILING((_xlpm.d-100)/10,1)*運賃マスター!$B$16),IF(_xlpm.vt="3t",IF(_xlpm.d<=100,IFERROR(VLOOKUP(_xlpm.d,運賃マスター!$E$5:$F$14,2,TRUE),運賃マスター!$F$5),運賃マスター!$F$17+CEILING((_xlpm.d-100)/10,1)*運賃マスター!$F$16),IF(_xlpm.vt="1t",IF(_xlpm.d<=100,IFERROR(VLOOKUP(_xlpm.d,運賃マスター!$I$5:$J$14,2,TRUE),運賃マスター!$J$5),運賃マスター!$J$17+CEILING((_xlpm.d-100)/10,1)*運賃マスター!$J$16),IF(_xlpm.vt="軽",IF(_xlpm.d<=50,IFERROR(VLOOKUP(_xlpm.d,運賃マスター!$M$5:$N$14,2,TRUE),運賃マスター!$N$5),IF(_xlpm.d<=100,運賃マスター!$N$15+(_xlpm.d-50)*運賃マスター!$N$16,運賃マスター!$N$17+(_xlpm.d-100)*運賃マスター!$N$18)),IF(_xlpm.vt="3tPG",IF(_xlpm.d<=100,IFERROR(VLOOKUP(_xlpm.d,運賃マスター!$Q$5:$R$14,2,TRUE),運賃マスター!$R$5),運賃マスター!$R$17+CEILING((_xlpm.d-100)/10,1)*運賃マスター!$R$16),"")))))),""))
D19: 現在待機場所 | E19: 待機予定場所 | H19: 目標距離 | J19: =IF(OR(H19="",K19=""),"",IFERROR(_xlfn.LET(_xlpm.vt,VLOOKUP(IFERROR(VALUE(LEFT(H19,FIND("＊",H19&"＊")-1)),H19),運賃マスター!$A$22:$B$40,2,FALSE),_xlpm.d,K19,IF(_xlpm.vt="2t",IF(_xlpm.d<=100,IFERROR(VLOOKUP(_xlpm.d,運賃マスター!$A$5:$B$14,2,TRUE),運賃マスター!$B$5),運賃マスター!$B$17+CEILING((_xlpm.d-100)/10,1)*運賃マスター!$B$16),IF(_xlpm.vt="3t",IF(_xlpm.d<=100,IFERROR(VLOOKUP(_xlpm.d,運賃マスター!$E$5:$F$14,2,TRUE),運賃マスター!$F$5),運賃マスター!$F$17+CEILING((_xlpm.d-100)/10,1)*運賃マスター!$F$16),IF(_xlpm.vt="1t",IF(_xlpm.d<=100,IFERROR(VLOOKUP(_xlpm.d,運賃マスター!$I$5:$J$14,2,TRUE),運賃マスター!$J$5),運賃マスター!$J$17+CEILING((_xlpm.d-100)/10,1)*運賃マスター!$J$16),IF(_xlpm.vt="軽",IF(_xlpm.d<=50,IFERROR(VLOOKUP(_xlpm.d,運賃マスター!$M$5:$N$14,2,TRUE),運賃マスター!$N$5),IF(_xlpm.d<=100,運賃マスター!$N$15+(_xlpm.d-50)*運賃マスター!$N$16,運賃マスター!$N$17+(_xlpm.d-100)*運賃マスター!$N$18)),IF(_xlpm.vt="3tPG",IF(_xlpm.d<=100,IFERROR(VLOOKUP(_xlpm.d,運賃マスター!$Q$5:$R$14,2,TRUE),運賃マスター!$R$5),運賃マスター!$R$17+CEILING((_xlpm.d-100)/10,1)*運賃マスター!$R$16),"")))))),""))
B20: 2(255) | C20: 山岸
B21: 8(254) | C21: 砂川 | H21: 残距離 | J21: =IF(OR(H21="",K21=""),"",IFERROR(_xlfn.LET(_xlpm.vt,VLOOKUP(IFERROR(VALUE(LEFT(H21,FIND("＊",H21&"＊")-1)),H21),運賃マスター!$A$22:$B$40,2,FALSE),_xlpm.d,K21,IF(_xlpm.vt="2t",IF(_xlpm.d<=100,IFERROR(VLOOKUP(_xlpm.d,運賃マスター!$A$5:$B$14,2,TRUE),運賃マスター!$B$5),運賃マスター!$B$17+CEILING((_xlpm.d-100)/10,1)*運賃マスター!$B$16),IF(_xlpm.vt="3t",IF(_xlpm.d<=100,IFERROR(VLOOKUP(_xlpm.d,運賃マスター!$E$5:$F$14,2,TRUE),運賃マスター!$F$5),運賃マスター!$F$17+CEILING((_xlpm.d-100)/10,1)*運賃マスター!$F$16),IF(_xlpm.vt="1t",IF(_xlpm.d<=100,IFERROR(VLOOKUP(_xlpm.d,運賃マスター!$I$5:$J$14,2,TRUE),運賃マスター!$J$5),運賃マスター!$J$17+CEILING((_xlpm.d-100)/10,1)*運賃マスター!$J$16),IF(_xlpm.vt="軽",IF(_xlpm.d<=50,IFERROR(VLOOKUP(_xlpm.d,運賃マスター!$M$5:$N$14,2,TRUE),運賃マスター!$N$5),IF(_xlpm.d<=100,運賃マスター!$N$15+(_xlpm.d-50)*運賃マスター!$N$16,運賃マスター!$N$17+(_xlpm.d-100)*運賃マスター!$N$18)),IF(_xlpm.vt="3tPG",IF(_xlpm.d<=100,IFERROR(VLOOKUP(_xlpm.d,運賃マスター!$Q$5:$R$14,2,TRUE),運賃マスター!$R$5),運賃マスター!$R$17+CEILING((_xlpm.d-100)/10,1)*運賃マスター!$R$16),"")))))),""))
B22: 9(256) | C22: 前川
B23: 10(257) | J23: =IF(OR(H23="",K23=""),"",IFERROR(_xlfn.LET(_xlpm.vt,VLOOKUP(IFERROR(VALUE(LEFT(H23,FIND("＊",H23&"＊")-1)),H23),運賃マスター!$A$22:$B$40,2,FALSE),_xlpm.d,K23,IF(_xlpm.vt="2t",IF(_xlpm.d<=100,IFERROR(VLOOKUP(_xlpm.d,運賃マスター!$A$5:$B$14,2,TRUE),運賃マスター!$B$5),運賃マスター!$B$17+CEILING((_xlpm.d-100)/10,1)*運賃マスター!$B$16),IF(_xlpm.vt="3t",IF(_xlpm.d<=100,IFERROR(VLOOKUP(_xlpm.d,運賃マスター!$E$5:$F$14,2,TRUE),運賃マスター!$F$5),運賃マスター!$F$17+CEILING((_xlpm.d-100)/10,1)*運賃マスター!$F$16),IF(_xlpm.vt="1t",IF(_xlpm.d<=100,IFERROR(VLOOKUP(_xlpm.d,運賃マスター!$I$5:$J$14,2,TRUE),運賃マスター!$J$5),運賃マスター!$J$17+CEILING((_xlpm.d-100)/10,1)*運賃マスター!$J$16),IF(_xlpm.vt="軽",IF(_xlpm.d<=50,IFERROR(VLOOKUP(_xlpm.d,運賃マスター!$M$5:$N$14,2,TRUE),運賃マスター!$N$5),IF(_xlpm.d<=100,運賃マスター!$N$15+(_xlpm.d-50)*運賃マスター!$N$16,運賃マスター!$N$17+(_xlpm.d-100)*運賃マスター!$N$18)),IF(_xlpm.vt="3tPG",IF(_xlpm.d<=100,IFERROR(VLOOKUP(_xlpm.d,運賃マスター!$Q$5:$R$14,2,TRUE),運賃マスター!$R$5),運賃マスター!$R$17+CEILING((_xlpm.d-100)/10,1)*運賃マスター!$R$16),"")))))),""))
B24: 11(258) | C24: 郡司 | H24: 依頼件数 | J24: =IF(OR(H24="",K24=""),"",IFERROR(_xlfn.LET(_xlpm.vt,VLOOKUP(IFERROR(VALUE(LEFT(H24,FIND("＊",H24&"＊")-1)),H24),運賃マスター!$A$22:$B$40,2,FALSE),_xlpm.d,K24,IF(_xlpm.vt="2t",IF(_xlpm.d<=100,IFERROR(VLOOKUP(_xlpm.d,運賃マスター!$A$5:$B$14,2,TRUE),運賃マスター!$B$5),運賃マスター!$B$17+CEILING((_xlpm.d-100)/10,1)*運賃マスター!$B$16),IF(_xlpm.vt="3t",IF(_xlpm.d<=100,IFERROR(VLOOKUP(_xlpm.d,運賃マスター!$E$5:$F$14,2,TRUE),運賃マスター!$F$5),運賃マスター!$F$17+CEILING((_xlpm.d-100)/10,1)*運賃マスター!$F$16),IF(_xlpm.vt="1t",IF(_xlpm.d<=100,IFERROR(VLOOKUP(_xlpm.d,運賃マスター!$I$5:$J$14,2,TRUE),運賃マスター!$J$5),運賃マスター!$J$17+CEILING((_xlpm.d-100)/10,1)*運賃マスター!$J$16),IF(_xlpm.vt="軽",IF(_xlpm.d<=50,IFERROR(VLOOKUP(_xlpm.d,運賃マスター!$M$5:$N$14,2,TRUE),運賃マスター!$N$5),IF(_xlpm.d<=100,運賃マスター!$N$15+(_xlpm.d-50)*運賃マスター!$N$16,運賃マスター!$N$17+(_xlpm.d-100)*運賃マスター!$N$18)),IF(_xlpm.vt="3tPG",IF(_xlpm.d<=100,IFERROR(VLOOKUP(_xlpm.d,運賃マスター!$Q$5:$R$14,2,TRUE),運賃マスター!$R$5),運賃マスター!$R$17+CEILING((_xlpm.d-100)/10,1)*運賃マスター!$R$16),"")))))),""))
B25: 12(736)
B26: 13(737) | J26: =IF(OR(H26="",K26=""),"",IFERROR(_xlfn.LET(_xlpm.vt,VLOOKUP(IFERROR(VALUE(LEFT(H26,FIND("＊",H26&"＊")-1)),H26),運賃マスター!$A$22:$B$40,2,FALSE),_xlpm.d,K26,IF(_xlpm.vt="2t",IF(_xlpm.d<=100,IFERROR(VLOOKUP(_xlpm.d,運賃マスター!$A$5:$B$14,2,TRUE),運賃マスター!$B$5),運賃マスター!$B$17+CEILING((_xlpm.d-100)/10,1)*運賃マスター!$B$16),IF(_xlpm.vt="3t",IF(_xlpm.d<=100,IFERROR(VLOOKUP(_xlpm.d,運賃マスター!$E$5:$F$14,2,TRUE),運賃マスター!$F$5),運賃マスター!$F$17+CEILING((_xlpm.d-100)/10,1)*運賃マスター!$F$16),IF(_xlpm.vt="1t",IF(_xlpm.d<=100,IFERROR(VLOOKUP(_xlpm.d,運賃マスター!$I$5:$J$14,2,TRUE),運賃マスター!$J$5),運賃マスター!$J$17+CEILING((_xlpm.d-100)/10,1)*運賃マスター!$J$16),IF(_xlpm.vt="軽",IF(_xlpm.d<=50,IFERROR(VLOOKUP(_xlpm.d,運賃マスター!$M$5:$N$14,2,TRUE),運賃マスター!$N$5),IF(_xlpm.d<=100,運賃マスター!$N$15+(_xlpm.d-50)*運賃マスター!$N$16,運賃マスター!$N$17+(_xlpm.d-100)*運賃マスター!$N$18)),IF(_xlpm.vt="3tPG",IF(_xlpm.d<=100,IFERROR(VLOOKUP(_xlpm.d,運賃マスター!$Q$5:$R$14,2,TRUE),運賃マスター!$R$5),運賃マスター!$R$17+CEILING((_xlpm.d-100)/10,1)*運賃マスター!$R$16),"")))))),""))
B27: 14(738) | C27: 辻井 | J27: =IF(OR(H27="",K27=""),"",IFERROR(_xlfn.LET(_xlpm.vt,VLOOKUP(IFERROR(VALUE(LEFT(H27,FIND("＊",H27&"＊")-1)),H27),運賃マスター!$A$22:$B$40,2,FALSE),_xlpm.d,K27,IF(_xlpm.vt="2t",IF(_xlpm.d<=100,IFERROR(VLOOKUP(_xlpm.d,運賃マスター!$A$5:$B$14,2,TRUE),運賃マスター!$B$5),運賃マスター!$B$17+CEILING((_xlpm.d-100)/10,1)*運賃マスター!$B$16),IF(_xlpm.vt="3t",IF(_xlpm.d<=100,IFERROR(VLOOKUP(_xlpm.d,運賃マスター!$E$5:$F$14,2,TRUE),運賃マスター!$F$5),運賃マスター!$F$17+CEILING((_xlpm.d-100)/10,1)*運賃マスター!$F$16),IF(_xlpm.vt="1t",IF(_xlpm.d<=100,IFERROR(VLOOKUP(_xlpm.d,運賃マスター!$I$5:$J$14,2,TRUE),運賃マスター!$J$5),運賃マスター!$J$17+CEILING((_xlpm.d-100)/10,1)*運賃マスター!$J$16),IF(_xlpm.vt="軽",IF(_xlpm.d<=50,IFERROR(VLOOKUP(_xlpm.d,運賃マスター!$M$5:$N$14,2,TRUE),運賃マスター!$N$5),IF(_xlpm.d<=100,運賃マスター!$N$15+(_xlpm.d-50)*運賃マスター!$N$16,運賃マスター!$N$17+(_xlpm.d-100)*運賃マスター!$N$18)),IF(_xlpm.vt="3tPG",IF(_xlpm.d<=100,IFERROR(VLOOKUP(_xlpm.d,運賃マスター!$Q$5:$R$14,2,TRUE),運賃マスター!$R$5),運賃マスター!$R$17+CEILING((_xlpm.d-100)/10,1)*運賃マスター!$R$16),"")))))),""))
J28: =IF(OR(H28="",K28=""),"",IFERROR(_xlfn.LET(_xlpm.vt,VLOOKUP(IFERROR(VALUE(LEFT(H28,FIND("＊",H28&"＊")-1)),H28),運賃マスター!$A$22:$B$40,2,FALSE),_xlpm.d,K28,IF(_xlpm.vt="2t",IF(_xlpm.d<=100,IFERROR(VLOOKUP(_xlpm.d,運賃マスター!$A$5:$B$14,2,TRUE),運賃マスター!$B$5),運賃マスター!$B$17+CEILING((_xlpm.d-100)/10,1)*運賃マスター!$B$16),IF(_xlpm.vt="3t",IF(_xlpm.d<=100,IFERROR(VLOOKUP(_xlpm.d,運賃マスター!$E$5:$F$14,2,TRUE),運賃マスター!$F$5),運賃マスター!$F$17+CEILING((_xlpm.d-100)/10,1)*運賃マスター!$F$16),IF(_xlpm.vt="1t",IF(_xlpm.d<=100,IFERROR(VLOOKUP(_xlpm.d,運賃マスター!$I$5:$J$14,2,TRUE),運賃マスター!$J$5),運賃マスター!$J$17+CEILING((_xlpm.d-100)/10,1)*運賃マスター!$J$16),IF(_xlpm.vt="軽",IF(_xlpm.d<=50,IFERROR(VLOOKUP(_xlpm.d,運賃マスター!$M$5:$N$14,2,TRUE),運賃マスター!$N$5),IF(_xlpm.d<=100,運賃マスター!$N$15+(_xlpm.d-50)*運賃マスター!$N$16,運賃マスター!$N$17+(_xlpm.d-100)*運賃マスター!$N$18)),IF(_xlpm.vt="3tPG",IF(_xlpm.d<=100,IFERROR(VLOOKUP(_xlpm.d,運賃マスター!$Q$5:$R$14,2,TRUE),運賃マスター!$R$5),運賃マスター!$R$17+CEILING((_xlpm.d-100)/10,1)*運賃マスター!$R$16),"")))))),""))
B29: 7290 | C29: 佐藤 | J29: =IF(OR(H29="",K29=""),"",IFERROR(_xlfn.LET(_xlpm.vt,VLOOKUP(IFERROR(VALUE(LEFT(H29,FIND("＊",H29&"＊")-1)),H29),運賃マスター!$A$22:$B$40,2,FALSE),_xlpm.d,K29,IF(_xlpm.vt="2t",IF(_xlpm.d<=100,IFERROR(VLOOKUP(_xlpm.d,運賃マスター!$A$5:$B$14,2,TRUE),運賃マスター!$B$5),運賃マスター!$B$17+CEILING((_xlpm.d-100)/10,1)*運賃マスター!$B$16),IF(_xlpm.vt="3t",IF(_xlpm.d<=100,IFERROR(VLOOKUP(_xlpm.d,運賃マスター!$E$5:$F$14,2,TRUE),運賃マスター!$F$5),運賃マスター!$F$17+CEILING((_xlpm.d-100)/10,1)*運賃マスター!$F$16),IF(_xlpm.vt="1t",IF(_xlpm.d<=100,IFERROR(VLOOKUP(_xlpm.d,運賃マスター!$I$5:$J$14,2,TRUE),運賃マスター!$J$5),運賃マスター!$J$17+CEILING((_xlpm.d-100)/10,1)*運賃マスター!$J$16),IF(_xlpm.vt="軽",IF(_xlpm.d<=50,IFERROR(VLOOKUP(_xlpm.d,運賃マスター!$M$5:$N$14,2,TRUE),運賃マスター!$N$5),IF(_xlpm.d<=100,運賃マスター!$N$15+(_xlpm.d-50)*運賃マスター!$N$16,運賃マスター!$N$17+(_xlpm.d-100)*運賃マスター!$N$18)),IF(_xlpm.vt="3tPG",IF(_xlpm.d<=100,IFERROR(VLOOKUP(_xlpm.d,運賃マスター!$Q$5:$R$14,2,TRUE),運賃マスター!$R$5),運賃マスター!$R$17+CEILING((_xlpm.d-100)/10,1)*運賃マスター!$R$16),"")))))),""))
B30: 7291 | C30: 末次 | J30: =IF(OR(H30="",K30=""),"",IFERROR(_xlfn.LET(_xlpm.vt,VLOOKUP(IFERROR(VALUE(LEFT(H30,FIND("＊",H30&"＊")-1)),H30),運賃マスター!$A$22:$B$40,2,FALSE),_xlpm.d,K30,IF(_xlpm.vt="2t",IF(_xlpm.d<=100,IFERROR(VLOOKUP(_xlpm.d,運賃マスター!$A$5:$B$14,2,TRUE),運賃マスター!$B$5),運賃マスター!$B$17+CEILING((_xlpm.d-100)/10,1)*運賃マスター!$B$16),IF(_xlpm.vt="3t",IF(_xlpm.d<=100,IFERROR(VLOOKUP(_xlpm.d,運賃マスター!$E$5:$F$14,2,TRUE),運賃マスター!$F$5),運賃マスター!$F$17+CEILING((_xlpm.d-100)/10,1)*運賃マスター!$F$16),IF(_xlpm.vt="1t",IF(_xlpm.d<=100,IFERROR(VLOOKUP(_xlpm.d,運賃マスター!$I$5:$J$14,2,TRUE),運賃マスター!$J$5),運賃マスター!$J$17+CEILING((_xlpm.d-100)/10,1)*運賃マスター!$J$16),IF(_xlpm.vt="軽",IF(_xlpm.d<=50,IFERROR(VLOOKUP(_xlpm.d,運賃マスター!$M$5:$N$14,2,TRUE),運賃マスター!$N$5),IF(_xlpm.d<=100,運賃マスター!$N$15+(_xlpm.d-50)*運賃マスター!$N$16,運賃マスター!$N$17+(_xlpm.d-100)*運賃マスター!$N$18)),IF(_xlpm.vt="3tPG",IF(_xlpm.d<=100,IFERROR(VLOOKUP(_xlpm.d,運賃マスター!$Q$5:$R$14,2,TRUE),運賃マスター!$R$5),運賃マスター!$R$17+CEILING((_xlpm.d-100)/10,1)*運賃マスター!$R$16),"")))))),""))
J31: =IF(OR(H31="",K31=""),"",IFERROR(_xlfn.LET(_xlpm.vt,VLOOKUP(IFERROR(VALUE(LEFT(H31,FIND("＊",H31&"＊")-1)),H31),運賃マスター!$A$22:$B$40,2,FALSE),_xlpm.d,K31,IF(_xlpm.vt="2t",IF(_xlpm.d<=100,IFERROR(VLOOKUP(_xlpm.d,運賃マスター!$A$5:$B$14,2,TRUE),運賃マスター!$B$5),運賃マスター!$B$17+CEILING((_xlpm.d-100)/10,1)*運賃マスター!$B$16),IF(_xlpm.vt="3t",IF(_xlpm.d<=100,IFERROR(VLOOKUP(_xlpm.d,運賃マスター!$E$5:$F$14,2,TRUE),運賃マスター!$F$5),運賃マスター!$F$17+CEILING((_xlpm.d-100)/10,1)*運賃マスター!$F$16),IF(_xlpm.vt="1t",IF(_xlpm.d<=100,IFERROR(VLOOKUP(_xlpm.d,運賃マスター!$I$5:$J$14,2,TRUE),運賃マスター!$J$5),運賃マスター!$J$17+CEILING((_xlpm.d-100)/10,1)*運賃マスター!$J$16),IF(_xlpm.vt="軽",IF(_xlpm.d<=50,IFERROR(VLOOKUP(_xlpm.d,運賃マスター!$M$5:$N$14,2,TRUE),運賃マスター!$N$5),IF(_xlpm.d<=100,運賃マスター!$N$15+(_xlpm.d-50)*運賃マスター!$N$16,運賃マスター!$N$17+(_xlpm.d-100)*運賃マスター!$N$18)),IF(_xlpm.vt="3tPG",IF(_xlpm.d<=100,IFERROR(VLOOKUP(_xlpm.d,運賃マスター!$Q$5:$R$14,2,TRUE),運賃マスター!$R$5),運賃マスター!$R$17+CEILING((_xlpm.d-100)/10,1)*運賃マスター!$R$16),"")))))),""))
B32: 333 | C32: 金井/奥田 | J32: =IF(OR(H32="",K32=""),"",IFERROR(_xlfn.LET(_xlpm.vt,VLOOKUP(IFERROR(VALUE(LEFT(H32,FIND("＊",H32&"＊")-1)),H32),運賃マスター!$A$22:$B$40,2,FALSE),_xlpm.d,K32,IF(_xlpm.vt="2t",IF(_xlpm.d<=100,IFERROR(VLOOKUP(_xlpm.d,運賃マスター!$A$5:$B$14,2,TRUE),運賃マスター!$B$5),運賃マスター!$B$17+CEILING((_xlpm.d-100)/10,1)*運賃マスター!$B$16),IF(_xlpm.vt="3t",IF(_xlpm.d<=100,IFERROR(VLOOKUP(_xlpm.d,運賃マスター!$E$5:$F$14,2,TRUE),運賃マスター!$F$5),運賃マスター!$F$17+CEILING((_xlpm.d-100)/10,1)*運賃マスター!$F$16),IF(_xlpm.vt="1t",IF(_xlpm.d<=100,IFERROR(VLOOKUP(_xlpm.d,運賃マスター!$I$5:$J$14,2,TRUE),運賃マスター!$J$5),運賃マスター!$J$17+CEILING((_xlpm.d-100)/10,1)*運賃マスター!$J$16),IF(_xlpm.vt="軽",IF(_xlpm.d<=50,IFERROR(VLOOKUP(_xlpm.d,運賃マスター!$M$5:$N$14,2,TRUE),運賃マスター!$N$5),IF(_xlpm.d<=100,運賃マスター!$N$15+(_xlpm.d-50)*運賃マスター!$N$16,運賃マスター!$N$17+(_xlpm.d-100)*運賃マスター!$N$18)),IF(_xlpm.vt="3tPG",IF(_xlpm.d<=100,IFERROR(VLOOKUP(_xlpm.d,運賃マスター!$Q$5:$R$14,2,TRUE),運賃マスター!$R$5),運賃マスター!$R$17+CEILING((_xlpm.d-100)/10,1)*運賃マスター!$R$16),"")))))),""))
B33: 666 | C33: 徳留 | J33: =IF(OR(H33="",K33=""),"",IFERROR(_xlfn.LET(_xlpm.vt,VLOOKUP(IFERROR(VALUE(LEFT(H33,FIND("＊",H33&"＊")-1)),H33),運賃マスター!$A$22:$B$40,2,FALSE),_xlpm.d,K33,IF(_xlpm.vt="2t",IF(_xlpm.d<=100,IFERROR(VLOOKUP(_xlpm.d,運賃マスター!$A$5:$B$14,2,TRUE),運賃マスター!$B$5),運賃マスター!$B$17+CEILING((_xlpm.d-100)/10,1)*運賃マスター!$B$16),IF(_xlpm.vt="3t",IF(_xlpm.d<=100,IFERROR(VLOOKUP(_xlpm.d,運賃マスター!$E$5:$F$14,2,TRUE),運賃マスター!$F$5),運賃マスター!$F$17+CEILING((_xlpm.d-100)/10,1)*運賃マスター!$F$16),IF(_xlpm.vt="1t",IF(_xlpm.d<=100,IFERROR(VLOOKUP(_xlpm.d,運賃マスター!$I$5:$J$14,2,TRUE),運賃マスター!$J$5),運賃マスター!$J$17+CEILING((_xlpm.d-100)/10,1)*運賃マスター!$J$16),IF(_xlpm.vt="軽",IF(_xlpm.d<=50,IFERROR(VLOOKUP(_xlpm.d,運賃マスター!$M$5:$N$14,2,TRUE),運賃マスター!$N$5),IF(_xlpm.d<=100,運賃マスター!$N$15+(_xlpm.d-50)*運賃マスター!$N$16,運賃マスター!$N$17+(_xlpm.d-100)*運賃マスター!$N$18)),IF(_xlpm.vt="3tPG",IF(_xlpm.d<=100,IFERROR(VLOOKUP(_xlpm.d,運賃マスター!$Q$5:$R$14,2,TRUE),運賃マスター!$R$5),運賃マスター!$R$17+CEILING((_xlpm.d-100)/10,1)*運賃マスター!$R$16),"")))))),""))
B34: 777 | J34: =IF(OR(H34="",K34=""),"",IFERROR(_xlfn.LET(_xlpm.vt,VLOOKUP(IFERROR(VALUE(LEFT(H34,FIND("＊",H34&"＊")-1)),H34),運賃マスター!$A$22:$B$40,2,FALSE),_xlpm.d,K34,IF(_xlpm.vt="2t",IF(_xlpm.d<=100,IFERROR(VLOOKUP(_xlpm.d,運賃マスター!$A$5:$B$14,2,TRUE),運賃マスター!$B$5),運賃マスター!$B$17+CEILING((_xlpm.d-100)/10,1)*運賃マスター!$B$16),IF(_xlpm.vt="3t",IF(_xlpm.d<=100,IFERROR(VLOOKUP(_xlpm.d,運賃マスター!$E$5:$F$14,2,TRUE),運賃マスター!$F$5),運賃マスター!$F$17+CEILING((_xlpm.d-100)/10,1)*運賃マスター!$F$16),IF(_xlpm.vt="1t",IF(_xlpm.d<=100,IFERROR(VLOOKUP(_xlpm.d,運賃マスター!$I$5:$J$14,2,TRUE),運賃マスター!$J$5),運賃マスター!$J$17+CEILING((_xlpm.d-100)/10,1)*運賃マスター!$J$16),IF(_xlpm.vt="軽",IF(_xlpm.d<=50,IFERROR(VLOOKUP(_xlpm.d,運賃マスター!$M$5:$N$14,2,TRUE),運賃マスター!$N$5),IF(_xlpm.d<=100,運賃マスター!$N$15+(_xlpm.d-50)*運賃マスター!$N$16,運賃マスター!$N$17+(_xlpm.d-100)*運賃マスター!$N$18)),IF(_xlpm.vt="3tPG",IF(_xlpm.d<=100,IFERROR(VLOOKUP(_xlpm.d,運賃マスター!$Q$5:$R$14,2,TRUE),運賃マスター!$R$5),運賃マスター!$R$17+CEILING((_xlpm.d-100)/10,1)*運賃マスター!$R$16),"")))))),""))
B35: 330 | J35: =IF(OR(H35="",K35=""),"",IFERROR(_xlfn.LET(_xlpm.vt,VLOOKUP(IFERROR(VALUE(LEFT(H35,FIND("＊",H35&"＊")-1)),H35),運賃マスター!$A$22:$B$40,2,FALSE),_xlpm.d,K35,IF(_xlpm.vt="2t",IF(_xlpm.d<=100,IFERROR(VLOOKUP(_xlpm.d,運賃マスター!$A$5:$B$14,2,TRUE),運賃マスター!$B$5),運賃マスター!$B$17+CEILING((_xlpm.d-100)/10,1)*運賃マスター!$B$16),IF(_xlpm.vt="3t",IF(_xlpm.d<=100,IFERROR(VLOOKUP(_xlpm.d,運賃マスター!$E$5:$F$14,2,TRUE),運賃マスター!$F$5),運賃マスター!$F$17+CEILING((_xlpm.d-100)/10,1)*運賃マスター!$F$16),IF(_xlpm.vt="1t",IF(_xlpm.d<=100,IFERROR(VLOOKUP(_xlpm.d,運賃マスター!$I$5:$J$14,2,TRUE),運賃マスター!$J$5),運賃マスター!$J$17+CEILING((_xlpm.d-100)/10,1)*運賃マスター!$J$16),IF(_xlpm.vt="軽",IF(_xlpm.d<=50,IFERROR(VLOOKUP(_xlpm.d,運賃マスター!$M$5:$N$14,2,TRUE),運賃マスター!$N$5),IF(_xlpm.d<=100,運賃マスター!$N$15+(_xlpm.d-50)*運賃マスター!$N$16,運賃マスター!$N$17+(_xlpm.d-100)*運賃マスター!$N$18)),IF(_xlpm.vt="3tPG",IF(_xlpm.d<=100,IFERROR(VLOOKUP(_xlpm.d,運賃マスター!$Q$5:$R$14,2,TRUE),運賃マスター!$R$5),運賃マスター!$R$17+CEILING((_xlpm.d-100)/10,1)*運賃マスター!$R$16),"")))))),""))
B36: 990 | C36: 山原 | J36: =IF(OR(H36="",K36=""),"",IFERROR(_xlfn.LET(_xlpm.vt,VLOOKUP(IFERROR(VALUE(LEFT(H36,FIND("＊",H36&"＊")-1)),H36),運賃マスター!$A$22:$B$40,2,FALSE),_xlpm.d,K36,IF(_xlpm.vt="2t",IF(_xlpm.d<=100,IFERROR(VLOOKUP(_xlpm.d,運賃マスター!$A$5:$B$14,2,TRUE),運賃マスター!$B$5),運賃マスター!$B$17+CEILING((_xlpm.d-100)/10,1)*運賃マスター!$B$16),IF(_xlpm.vt="3t",IF(_xlpm.d<=100,IFERROR(VLOOKUP(_xlpm.d,運賃マスター!$E$5:$F$14,2,TRUE),運賃マスター!$F$5),運賃マスター!$F$17+CEILING((_xlpm.d-100)/10,1)*運賃マスター!$F$16),IF(_xlpm.vt="1t",IF(_xlpm.d<=100,IFERROR(VLOOKUP(_xlpm.d,運賃マスター!$I$5:$J$14,2,TRUE),運賃マスター!$J$5),運賃マスター!$J$17+CEILING((_xlpm.d-100)/10,1)*運賃マスター!$J$16),IF(_xlpm.vt="軽",IF(_xlpm.d<=50,IFERROR(VLOOKUP(_xlpm.d,運賃マスター!$M$5:$N$14,2,TRUE),運賃マスター!$N$5),IF(_xlpm.d<=100,運賃マスター!$N$15+(_xlpm.d-50)*運賃マスター!$N$16,運賃マスター!$N$17+(_xlpm.d-100)*運賃マスター!$N$18)),IF(_xlpm.vt="3tPG",IF(_xlpm.d<=100,IFERROR(VLOOKUP(_xlpm.d,運賃マスター!$Q$5:$R$14,2,TRUE),運賃マスター!$R$5),運賃マスター!$R$17+CEILING((_xlpm.d-100)/10,1)*運賃マスター!$R$16),"")))))),""))
J37: =IF(OR(H37="",K37=""),"",IFERROR(_xlfn.LET(_xlpm.vt,VLOOKUP(IFERROR(VALUE(LEFT(H37,FIND("＊",H37&"＊")-1)),H37),運賃マスター!$A$22:$B$40,2,FALSE),_xlpm.d,K37,IF(_xlpm.vt="2t",IF(_xlpm.d<=100,IFERROR(VLOOKUP(_xlpm.d,運賃マスター!$A$5:$B$14,2,TRUE),運賃マスター!$B$5),運賃マスター!$B$17+CEILING((_xlpm.d-100)/10,1)*運賃マスター!$B$16),IF(_xlpm.vt="3t",IF(_xlpm.d<=100,IFERROR(VLOOKUP(_xlpm.d,運賃マスター!$E$5:$F$14,2,TRUE),運賃マスター!$F$5),運賃マスター!$F$17+CEILING((_xlpm.d-100)/10,1)*運賃マスター!$F$16),IF(_xlpm.vt="1t",IF(_xlpm.d<=100,IFERROR(VLOOKUP(_xlpm.d,運賃マスター!$I$5:$J$14,2,TRUE),運賃マスター!$J$5),運賃マスター!$J$17+CEILING((_xlpm.d-100)/10,1)*運賃マスター!$J$16),IF(_xlpm.vt="軽",IF(_xlpm.d<=50,IFERROR(VLOOKUP(_xlpm.d,運賃マスター!$M$5:$N$14,2,TRUE),運賃マスター!$N$5),IF(_xlpm.d<=100,運賃マスター!$N$15+(_xlpm.d-50)*運賃マスター!$N$16,運賃マスター!$N$17+(_xlpm.d-100)*運賃マスター!$N$18)),IF(_xlpm.vt="3tPG",IF(_xlpm.d<=100,IFERROR(VLOOKUP(_xlpm.d,運賃マスター!$Q$5:$R$14,2,TRUE),運賃マスター!$R$5),運賃マスター!$R$17+CEILING((_xlpm.d-100)/10,1)*運賃マスター!$R$16),"")))))),""))
C38: 出発→到着 | D38: 備考 | J38: =IF(OR(H38="",K38=""),"",IFERROR(_xlfn.LET(_xlpm.vt,VLOOKUP(IFERROR(VALUE(LEFT(H38,FIND("＊",H38&"＊")-1)),H38),運賃マスター!$A$22:$B$40,2,FALSE),_xlpm.d,K38,IF(_xlpm.vt="2t",IF(_xlpm.d<=100,IFERROR(VLOOKUP(_xlpm.d,運賃マスター!$A$5:$B$14,2,TRUE),運賃マスター!$B$5),運賃マスター!$B$17+CEILING((_xlpm.d-100)/10,1)*運賃マスター!$B$16),IF(_xlpm.vt="3t",IF(_xlpm.d<=100,IFERROR(VLOOKUP(_xlpm.d,運賃マスター!$E$5:$F$14,2,TRUE),運賃マスター!$F$5),運賃マスター!$F$17+CEILING((_xlpm.d-100)/10,1)*運賃マスター!$F$16),IF(_xlpm.vt="1t",IF(_xlpm.d<=100,IFERROR(VLOOKUP(_xlpm.d,運賃マスター!$I$5:$J$14,2,TRUE),運賃マスター!$J$5),運賃マスター!$J$17+CEILING((_xlpm.d-100)/10,1)*運賃マスター!$J$16),IF(_xlpm.vt="軽",IF(_xlpm.d<=50,IFERROR(VLOOKUP(_xlpm.d,運賃マスター!$M$5:$N$14,2,TRUE),運賃マスター!$N$5),IF(_xlpm.d<=100,運賃マスター!$N$15+(_xlpm.d-50)*運賃マスター!$N$16,運賃マスター!$N$17+(_xlpm.d-100)*運賃マスター!$N$18)),IF(_xlpm.vt="3tPG",IF(_xlpm.d<=100,IFERROR(VLOOKUP(_xlpm.d,運賃マスター!$Q$5:$R$14,2,TRUE),運賃マスター!$R$5),運賃マスター!$R$17+CEILING((_xlpm.d-100)/10,1)*運賃マスター!$R$16),"")))))),""))
B39: ① | C39: 東→西 | D39: ①Aチーム優先 | J39: =IF(OR(H39="",K39=""),"",IFERROR(_xlfn.LET(_xlpm.vt,VLOOKUP(IFERROR(VALUE(LEFT(H39,FIND("＊",H39&"＊")-1)),H39),運賃マスター!$A$22:$B$40,2,FALSE),_xlpm.d,K39,IF(_xlpm.vt="2t",IF(_xlpm.d<=100,IFERROR(VLOOKUP(_xlpm.d,運賃マスター!$A$5:$B$14,2,TRUE),運賃マスター!$B$5),運賃マスター!$B$17+CEILING((_xlpm.d-100)/10,1)*運賃マスター!$B$16),IF(_xlpm.vt="3t",IF(_xlpm.d<=100,IFERROR(VLOOKUP(_xlpm.d,運賃マスター!$E$5:$F$14,2,TRUE),運賃マスター!$F$5),運賃マスター!$F$17+CEILING((_xlpm.d-100)/10,1)*運賃マスター!$F$16),IF(_xlpm.vt="1t",IF(_xlpm.d<=100,IFERROR(VLOOKUP(_xlpm.d,運賃マスター!$I$5:$J$14,2,TRUE),運賃マスター!$J$5),運賃マスター!$J$17+CEILING((_xlpm.d-100)/10,1)*運賃マスター!$J$16),IF(_xlpm.vt="軽",IF(_xlpm.d<=50,IFERROR(VLOOKUP(_xlpm.d,運賃マスター!$M$5:$N$14,2,TRUE),運賃マスター!$N$5),IF(_xlpm.d<=100,運賃マスター!$N$15+(_xlpm.d-50)*運賃マスター!$N$16,運賃マスター!$N$17+(_xlpm.d-100)*運賃マスター!$N$18)),IF(_xlpm.vt="3tPG",IF(_xlpm.d<=100,IFERROR(VLOOKUP(_xlpm.d,運賃マスター!$Q$5:$R$14,2,TRUE),運賃マスター!$R$5),運賃マスター!$R$17+CEILING((_xlpm.d-100)/10,1)*運賃マスター!$R$16),"")))))),""))
B40: ② | C40: 東→東 | D40: ②急ぎ案件の場合、道路状況も伝えてあげる。 | J40: =IF(OR(H40="",K40=""),"",IFERROR(_xlfn.LET(_xlpm.vt,VLOOKUP(IFERROR(VALUE(LEFT(H40,FIND("＊",H40&"＊")-1)),H40),運賃マスター!$A$22:$B$40,2,FALSE),_xlpm.d,K40,IF(_xlpm.vt="2t",IF(_xlpm.d<=100,IFERROR(VLOOKUP(_xlpm.d,運賃マスター!$A$5:$B$14,2,TRUE),運賃マスター!$B$5),運賃マスター!$B$17+CEILING((_xlpm.d-100)/10,1)*運賃マスター!$B$16),IF(_xlpm.vt="3t",IF(_xlpm.d<=100,IFERROR(VLOOKUP(_xlpm.d,運賃マスター!$E$5:$F$14,2,TRUE),運賃マスター!$F$5),運賃マスター!$F$17+CEILING((_xlpm.d-100)/10,1)*運賃マスター!$F$16),IF(_xlpm.vt="1t",IF(_xlpm.d<=100,IFERROR(VLOOKUP(_xlpm.d,運賃マスター!$I$5:$J$14,2,TRUE),運賃マスター!$J$5),運賃マスター!$J$17+CEILING((_xlpm.d-100)/10,1)*運賃マスター!$J$16),IF(_xlpm.vt="軽",IF(_xlpm.d<=50,IFERROR(VLOOKUP(_xlpm.d,運賃マスター!$M$5:$N$14,2,TRUE),運賃マスター!$N$5),IF(_xlpm.d<=100,運賃マスター!$N$15+(_xlpm.d-50)*運賃マスター!$N$16,運賃マスター!$N$17+(_xlpm.d-100)*運賃マスター!$N$18)),IF(_xlpm.vt="3tPG",IF(_xlpm.d<=100,IFERROR(VLOOKUP(_xlpm.d,運賃マスター!$Q$5:$R$14,2,TRUE),運賃マスター!$R$5),運賃マスター!$R$17+CEILING((_xlpm.d-100)/10,1)*運賃マスター!$R$16),"")))))),""))
B41: ③ | C41: 西→東 | D41: ③各ドライバーの位置からの帰社のタイミング・夕方の配置 | J41: =IF(OR(H41="",K41=""),"",IFERROR(_xlfn.LET(_xlpm.vt,VLOOKUP(IFERROR(VALUE(LEFT(H41,FIND("＊",H41&"＊")-1)),H41),運賃マスター!$A$22:$B$40,2,FALSE),_xlpm.d,K41,IF(_xlpm.vt="2t",IF(_xlpm.d<=100,IFERROR(VLOOKUP(_xlpm.d,運賃マスター!$A$5:$B$14,2,TRUE),運賃マスター!$B$5),運賃マスター!$B$17+CEILING((_xlpm.d-100)/10,1)*運賃マスター!$B$16),IF(_xlpm.vt="3t",IF(_xlpm.d<=100,IFERROR(VLOOKUP(_xlpm.d,運賃マスター!$E$5:$F$14,2,TRUE),運賃マスター!$F$5),運賃マスター!$F$17+CEILING((_xlpm.d-100)/10,1)*運賃マスター!$F$16),IF(_xlpm.vt="1t",IF(_xlpm.d<=100,IFERROR(VLOOKUP(_xlpm.d,運賃マスター!$I$5:$J$14,2,TRUE),運賃マスター!$J$5),運賃マスター!$J$17+CEILING((_xlpm.d-100)/10,1)*運賃マスター!$J$16),IF(_xlpm.vt="軽",IF(_xlpm.d<=50,IFERROR(VLOOKUP(_xlpm.d,運賃マスター!$M$5:$N$14,2,TRUE),運賃マスター!$N$5),IF(_xlpm.d<=100,運賃マスター!$N$15+(_xlpm.d-50)*運賃マスター!$N$16,運賃マスター!$N$17+(_xlpm.d-100)*運賃マスター!$N$18)),IF(_xlpm.vt="3tPG",IF(_xlpm.d<=100,IFERROR(VLOOKUP(_xlpm.d,運賃マスター!$Q$5:$R$14,2,TRUE),運賃マスター!$R$5),運賃マスター!$R$17+CEILING((_xlpm.d-100)/10,1)*運賃マスター!$R$16),"")))))),""))
B42: ④ | C42: 西→西 | D42: ④依頼を受ける際の、希望時間と現状の位置。行けるか行けないかの判断をしっかりと。
...

Sheet 6 1  (2)
B2: 46174 | D2: NO.１
B3: 荷主 | C3: 種類 | D3: 積込地 | E3: 積降地 | F3: ユーザー名(搬入/搬出) | G3: 時間 | H3: 号車 | J3: 距離 | K3: 特記事項 | L3: 距離 | M3: メモ
B4: 山岸：休み
A5: =IF(B5="","",COUNTA($B$5:B5)) | I5: =IFERROR(_xlfn.XLOOKUP(H5,案件・ドライバー一覧!$L$3:$L$17,案件・ドライバー一覧!$M$3:$M$17,""),"") | K5: {=IF(OR(H5="",L5=""),"",IFERROR(_xlfn.LET(_xlpm.vt,VLOOKUP(IFERROR(VALUE(LEFT(H5,FIND("＊",H5&"＊")-1)),H5),運賃マスター!$A$22:$B$40,2,FALSE),_xlpm.d,L5,IF(OR(_xlpm.vt="2t",_xlpm.vt="2tユニック",_xlpm.vt="2ｔユニック"),IF(_xlpm.d<=100,IFERROR(INDEX(運賃マスター!$B$5:$B$14,MATCH(1,(運賃マスター!$A$5:$A$14>=_xlpm.d)*1,0)),運賃マスター!$B$5),運賃マスター!$B$17+CEILING((_xlpm.d-100)/10,1)*運賃マスター!$B$16),IF(OR(_xlpm.vt="3t",_xlpm.vt="3tユニック",_xlpm.vt="3ｔユニック"),IF(_xlpm.d<=100,IFERROR(INDEX(運賃マスター!$F$5:$F$14,MATCH(1,(運賃マスター!$E$5:$E$14>=_xlpm.d)*1,0)),運賃マスター!$F$5),運賃マスター!$F$17+CEILING((_xlpm.d-100)/10,1)*運賃マスター!$F$16),IF(_xlpm.vt="1t",IF(_xlpm.d<=100,IFERROR(INDEX(運賃マスター!$J$5:$J$14,MATCH(1,(運賃マスター!$I$5:$I$14>=_xlpm.d)*1,0)),運賃マスター!$J$5),運賃マスター!$J$17+CEILING((_xlpm.d-100)/10,1)*運賃マスター!$J$16),IF(_xlpm.vt="軽",IF(_xlpm.d<=50,IFERROR(INDEX(運賃マスター!$N$5:$N$14,MATCH(1,(運賃マスター!$M$5:$M$14>=_xlpm.d)*1,0)),運賃マスター!$N$5),IF(_xlpm.d<=100,運賃マスター!$N$15+(_xlpm.d-50)*運賃マスター!$N$16,運賃マスター!$N$17+(_xlpm.d-100)*運賃マスター!$N$18)),IF(_xlpm.vt="3tPG",IF(_xlpm.d<=100,IFERROR(INDEX(運賃マスター!$R$5:$R$14,MATCH(1,(運賃マスター!$Q$5:$Q$14>=_xlpm.d)*1,0)),運賃マスター!$R$5),運賃マスター!$R$17+CEILING((_xlpm.d-100)/10,1)*運賃マスター!$R$16),"")))))),""))}
A6: =IF(B6="","",COUNTA($B$5:B6)) | I6: =IFERROR(_xlfn.XLOOKUP(H6,案件・ドライバー一覧!$L$3:$L$17,案件・ドライバー一覧!$M$3:$M$17,""),"")
A7: =IF(B7="","",COUNTA($B$5:B7)) | I7: =IFERROR(_xlfn.XLOOKUP(H7,案件・ドライバー一覧!$L$3:$L$17,案件・ドライバー一覧!$M$3:$M$17,""),"") | K7: {=IF(OR(H7="",L7=""),"",IFERROR(_xlfn.LET(_xlpm.vt,VLOOKUP(IFERROR(VALUE(LEFT(H7,FIND("＊",H7&"＊")-1)),H7),運賃マスター!$A$22:$B$40,2,FALSE),_xlpm.d,L7,IF(OR(_xlpm.vt="2t",_xlpm.vt="2tユニック",_xlpm.vt="2ｔユニック"),IF(_xlpm.d<=100,IFERROR(INDEX(運賃マスター!$B$5:$B$14,MATCH(1,(運賃マスター!$A$5:$A$14>=_xlpm.d)*1,0)),運賃マスター!$B$5),運賃マスター!$B$17+CEILING((_xlpm.d-100)/10,1)*運賃マスター!$B$16),IF(OR(_xlpm.vt="3t",_xlpm.vt="3tユニック",_xlpm.vt="3ｔユニック"),IF(_xlpm.d<=100,IFERROR(INDEX(運賃マスター!$F$5:$F$14,MATCH(1,(運賃マスター!$E$5:$E$14>=_xlpm.d)*1,0)),運賃マスター!$F$5),運賃マスター!$F$17+CEILING((_xlpm.d-100)/10,1)*運賃マスター!$F$16),IF(_xlpm.vt="1t",IF(_xlpm.d<=100,IFERROR(INDEX(運賃マスター!$J$5:$J$14,MATCH(1,(運賃マスター!$I$5:$I$14>=_xlpm.d)*1,0)),運賃マスター!$J$5),運賃マスター!$J$17+CEILING((_xlpm.d-100)/10,1)*運賃マスター!$J$16),IF(_xlpm.vt="軽",IF(_xlpm.d<=50,IFERROR(INDEX(運賃マスター!$N$5:$N$14,MATCH(1,(運賃マスター!$M$5:$M$14>=_xlpm.d)*1,0)),運賃マスター!$N$5),IF(_xlpm.d<=100,運賃マスター!$N$15+(_xlpm.d-50)*運賃マスター!$N$16,運賃マスター!$N$17+(_xlpm.d-100)*運賃マスター!$N$18)),IF(_xlpm.vt="3tPG",IF(_xlpm.d<=100,IFERROR(INDEX(運賃マスター!$R$5:$R$14,MATCH(1,(運賃マスター!$Q$5:$Q$14>=_xlpm.d)*1,0)),運賃マスター!$R$5),運賃マスター!$R$17+CEILING((_xlpm.d-100)/10,1)*運賃マスター!$R$16),"")))))),""))}
A8: =IF(B8="","",COUNTA($B$5:B8)) | I8: =IFERROR(_xlfn.XLOOKUP(H8,案件・ドライバー一覧!$L$3:$L$17,案件・ドライバー一覧!$M$3:$M$17,""),"")
A9: =IF(B9="","",COUNTA($B$5:B9)) | I9: =IFERROR(_xlfn.XLOOKUP(H9,案件・ドライバー一覧!$L$3:$L$17,案件・ドライバー一覧!$M$3:$M$17,""),"") | K9: {=IF(OR(H9="",L9=""),"",IFERROR(_xlfn.LET(_xlpm.vt,VLOOKUP(IFERROR(VALUE(LEFT(H9,FIND("＊",H9&"＊")-1)),H9),運賃マスター!$A$22:$B$40,2,FALSE),_xlpm.d,L9,IF(OR(_xlpm.vt="2t",_xlpm.vt="2tユニック",_xlpm.vt="2ｔユニック"),IF(_xlpm.d<=100,IFERROR(INDEX(運賃マスター!$B$5:$B$14,MATCH(1,(運賃マスター!$A$5:$A$14>=_xlpm.d)*1,0)),運賃マスター!$B$5),運賃マスター!$B$17+CEILING((_xlpm.d-100)/10,1)*運賃マスター!$B$16),IF(OR(_xlpm.vt="3t",_xlpm.vt="3tユニック",_xlpm.vt="3ｔユニック"),IF(_xlpm.d<=100,IFERROR(INDEX(運賃マスター!$F$5:$F$14,MATCH(1,(運賃マスター!$E$5:$E$14>=_xlpm.d)*1,0)),運賃マスター!$F$5),運賃マスター!$F$17+CEILING((_xlpm.d-100)/10,1)*運賃マスター!$F$16),IF(_xlpm.vt="1t",IF(_xlpm.d<=100,IFERROR(INDEX(運賃マスター!$J$5:$J$14,MATCH(1,(運賃マスター!$I$5:$I$14>=_xlpm.d)*1,0)),運賃マスター!$J$5),運賃マスター!$J$17+CEILING((_xlpm.d-100)/10,1)*運賃マスター!$J$16),IF(_xlpm.vt="軽",IF(_xlpm.d<=50,IFERROR(INDEX(運賃マスター!$N$5:$N$14,MATCH(1,(運賃マスター!$M$5:$M$14>=_xlpm.d)*1,0)),運賃マスター!$N$5),IF(_xlpm.d<=100,運賃マスター!$N$15+(_xlpm.d-50)*運賃マスター!$N$16,運賃マスター!$N$17+(_xlpm.d-100)*運賃マスター!$N$18)),IF(_xlpm.vt="3tPG",IF(_xlpm.d<=100,IFERROR(INDEX(運賃マスター!$R$5:$R$14,MATCH(1,(運賃マスター!$Q$5:$Q$14>=_xlpm.d)*1,0)),運賃マスター!$R$5),運賃マスター!$R$17+CEILING((_xlpm.d-100)/10,1)*運賃マスター!$R$16),"")))))),""))}
A10: =IF(B10="","",COUNTA($B$5:B10)) | I10: =IFERROR(_xlfn.XLOOKUP(H10,案件・ドライバー一覧!$L$3:$L$17,案件・ドライバー一覧!$M$3:$M$17,""),"")
A11: =IF(B11="","",COUNTA($B$5:B11)) | I11: =IFERROR(_xlfn.XLOOKUP(H11,案件・ドライバー一覧!$L$3:$L$17,案件・ドライバー一覧!$M$3:$M$17,""),"")
A12: =IF(B12="","",COUNTA($B$5:B12)) | I12: =IFERROR(_xlfn.XLOOKUP(H12,案件・ドライバー一覧!$L$3:$L$17,案件・ドライバー一覧!$M$3:$M$17,""),"")
A13: =IF(B13="","",COUNTA($B$5:B13)) | I13: =IFERROR(_xlfn.XLOOKUP(H13,案件・ドライバー一覧!$L$3:$L$17,案件・ドライバー一覧!$M$3:$M$17,""),"")
A14: =IF(B14="","",COUNTA($B$5:B14)) | I14: =IFERROR(_xlfn.XLOOKUP(H14,案件・ドライバー一覧!$L$3:$L$17,案件・ドライバー一覧!$M$3:$M$17,""),"") | K14: {=IF(OR(H14="",L14=""),"",IFERROR(_xlfn.LET(_xlpm.vt,VLOOKUP(IFERROR(VALUE(LEFT(H14,FIND("＊",H14&"＊")-1)),H14),運賃マスター!$A$22:$B$40,2,FALSE),_xlpm.d,L14,IF(OR(_xlpm.vt="2t",_xlpm.vt="2tユニック",_xlpm.vt="2ｔユニック"),IF(_xlpm.d<=100,IFERROR(INDEX(運賃マスター!$B$5:$B$14,MATCH(1,(運賃マスター!$A$5:$A$14>=_xlpm.d)*1,0)),運賃マスター!$B$5),運賃マスター!$B$17+CEILING((_xlpm.d-100)/10,1)*運賃マスター!$B$16),IF(OR(_xlpm.vt="3t",_xlpm.vt="3tユニック",_xlpm.vt="3ｔユニック"),IF(_xlpm.d<=100,IFERROR(INDEX(運賃マスター!$F$5:$F$14,MATCH(1,(運賃マスター!$E$5:$E$14>=_xlpm.d)*1,0)),運賃マスター!$F$5),運賃マスター!$F$17+CEILING((_xlpm.d-100)/10,1)*運賃マスター!$F$16),IF(_xlpm.vt="1t",IF(_xlpm.d<=100,IFERROR(INDEX(運賃マスター!$J$5:$J$14,MATCH(1,(運賃マスター!$I$5:$I$14>=_xlpm.d)*1,0)),運賃マスター!$J$5),運賃マスター!$J$17+CEILING((_xlpm.d-100)/10,1)*運賃マスター!$J$16),IF(_xlpm.vt="軽",IF(_xlpm.d<=50,IFERROR(INDEX(運賃マスター!$N$5:$N$14,MATCH(1,(運賃マスター!$M$5:$M$14>=_xlpm.d)*1,0)),運賃マスター!$N$5),IF(_xlpm.d<=100,運賃マスター!$N$15+(_xlpm.d-50)*運賃マスター!$N$16,運賃マスター!$N$17+(_xlpm.d-100)*運賃マスター!$N$18)),IF(_xlpm.vt="3tPG",IF(_xlpm.d<=100,IFERROR(INDEX(運賃マスター!$R$5:$R$14,MATCH(1,(運賃マスター!$Q$5:$Q$14>=_xlpm.d)*1,0)),運賃マスター!$R$5),運賃マスター!$R$17+CEILING((_xlpm.d-100)/10,1)*運賃マスター!$R$16),"")))))),""))}
A15: =IF(B15="","",COUNTA($B$5:B15)) | I15: =IFERROR(_xlfn.XLOOKUP(H15,案件・ドライバー一覧!$L$3:$L$17,案件・ドライバー一覧!$M$3:$M$17,""),"")
A16: =IF(B16="","",COUNTA($B$5:B16))
A17: =IF(B17="","",COUNTA($B$5:B17))
A18: =IF(B18="","",COUNTA($B$5:B18))
A19: =IF(B19="","",COUNTA($B$5:B19)) | K19: {=IF(OR(H19="",L19=""),"",IFERROR(_xlfn.LET(_xlpm.vt,VLOOKUP(IFERROR(VALUE(LEFT(H19,FIND("＊",H19&"＊")-1)),H19),運賃マスター!$A$22:$B$40,2,FALSE),_xlpm.d,L19,IF(OR(_xlpm.vt="2t",_xlpm.vt="2tユニック",_xlpm.vt="2ｔユニック"),IF(_xlpm.d<=100,IFERROR(INDEX(運賃マスター!$B$5:$B$14,MATCH(1,(運賃マスター!$A$5:$A$14>=_xlpm.d)*1,0)),運賃マスター!$B$5),運賃マスター!$B$17+CEILING((_xlpm.d-100)/10,1)*運賃マスター!$B$16),IF(OR(_xlpm.vt="3t",_xlpm.vt="3tユニック",_xlpm.vt="3ｔユニック"),IF(_xlpm.d<=100,IFERROR(INDEX(運賃マスター!$F$5:$F$14,MATCH(1,(運賃マスター!$E$5:$E$14>=_xlpm.d)*1,0)),運賃マスター!$F$5),運賃マスター!$F$17+CEILING((_xlpm.d-100)/10,1)*運賃マスター!$F$16),IF(_xlpm.vt="1t",IF(_xlpm.d<=100,IFERROR(INDEX(運賃マスター!$J$5:$J$14,MATCH(1,(運賃マスター!$I$5:$I$14>=_xlpm.d)*1,0)),運賃マスター!$J$5),運賃マスター!$J$17+CEILING((_xlpm.d-100)/10,1)*運賃マスター!$J$16),IF(_xlpm.vt="軽",IF(_xlpm.d<=50,IFERROR(INDEX(運賃マスター!$N$5:$N$14,MATCH(1,(運賃マスター!$M$5:$M$14>=_xlpm.d)*1,0)),運賃マスター!$N$5),IF(_xlpm.d<=100,運賃マスター!$N$15+(_xlpm.d-50)*運賃マスター!$N$16,運賃マスター!$N$17+(_xlpm.d-100)*運賃マスター!$N$18)),IF(_xlpm.vt="3tPG",IF(_xlpm.d<=100,IFERROR(INDEX(運賃マスター!$R$5:$R$14,MATCH(1,(運賃マスター!$Q$5:$Q$14>=_xlpm.d)*1,0)),運賃マスター!$R$5),運賃マスター!$R$17+CEILING((_xlpm.d-100)/10,1)*運賃マスター!$R$16),"")))))),""))}
A20: =IF(B20="","",COUNTA($B$5:B20)) | K20: {=IF(OR(H20="",L20=""),"",IFERROR(_xlfn.LET(_xlpm.vt,VLOOKUP(IFERROR(VALUE(LEFT(H20,FIND("＊",H20&"＊")-1)),H20),運賃マスター!$A$22:$B$40,2,FALSE),_xlpm.d,L20,IF(OR(_xlpm.vt="2t",_xlpm.vt="2tユニック",_xlpm.vt="2ｔユニック"),IF(_xlpm.d<=100,IFERROR(INDEX(運賃マスター!$B$5:$B$14,MATCH(1,(運賃マスター!$A$5:$A$14>=_xlpm.d)*1,0)),運賃マスター!$B$5),運賃マスター!$B$17+CEILING((_xlpm.d-100)/10,1)*運賃マスター!$B$16),IF(OR(_xlpm.vt="3t",_xlpm.vt="3tユニック",_xlpm.vt="3ｔユニック"),IF(_xlpm.d<=100,IFERROR(INDEX(運賃マスター!$F$5:$F$14,MATCH(1,(運賃マスター!$E$5:$E$14>=_xlpm.d)*1,0)),運賃マスター!$F$5),運賃マスター!$F$17+CEILING((_xlpm.d-100)/10,1)*運賃マスター!$F$16),IF(_xlpm.vt="1t",IF(_xlpm.d<=100,IFERROR(INDEX(運賃マスター!$J$5:$J$14,MATCH(1,(運賃マスター!$I$5:$I$14>=_xlpm.d)*1,0)),運賃マスター!$J$5),運賃マスター!$J$17+CEILING((_xlpm.d-100)/10,1)*運賃マスター!$J$16),IF(_xlpm.vt="軽",IF(_xlpm.d<=50,IFERROR(INDEX(運賃マスター!$N$5:$N$14,MATCH(1,(運賃マスター!$M$5:$M$14>=_xlpm.d)*1,0)),運賃マスター!$N$5),IF(_xlpm.d<=100,運賃マスター!$N$15+(_xlpm.d-50)*運賃マスター!$N$16,運賃マスター!$N$17+(_xlpm.d-100)*運賃マスター!$N$18)),IF(_xlpm.vt="3tPG",IF(_xlpm.d<=100,IFERROR(INDEX(運賃マスター!$R$5:$R$14,MATCH(1,(運賃マスター!$Q$5:$Q$14>=_xlpm.d)*1,0)),運賃マスター!$R$5),運賃マスター!$R$17+CEILING((_xlpm.d-100)/10,1)*運賃マスター!$R$16),"")))))),""))}
A21: =IF(B21="","",COUNTA($B$5:B21))
A22: =IF(B22="","",COUNTA($B$5:B22))
A23: =IF(B23="","",COUNTA($B$5:B23))
A24: =IF(B24="","",COUNTA($B$5:B24))
A25: =IF(B25="","",COUNTA($B$5:B25)) | K25: {=IF(OR(H25="",L25=""),"",IFERROR(_xlfn.LET(_xlpm.vt,VLOOKUP(IFERROR(VALUE(LEFT(H25,FIND("＊",H25&"＊")-1)),H25),運賃マスター!$A$22:$B$40,2,FALSE),_xlpm.d,L25,IF(OR(_xlpm.vt="2t",_xlpm.vt="2tユニック",_xlpm.vt="2ｔユニック"),IF(_xlpm.d<=100,IFERROR(INDEX(運賃マスター!$B$5:$B$14,MATCH(1,(運賃マスター!$A$5:$A$14>=_xlpm.d)*1,0)),運賃マスター!$B$5),運賃マスター!$B$17+CEILING((_xlpm.d-100)/10,1)*運賃マスター!$B$16),IF(OR(_xlpm.vt="3t",_xlpm.vt="3tユニック",_xlpm.vt="3ｔユニック"),IF(_xlpm.d<=100,IFERROR(INDEX(運賃マスター!$F$5:$F$14,MATCH(1,(運賃マスター!$E$5:$E$14>=_xlpm.d)*1,0)),運賃マスター!$F$5),運賃マスター!$F$17+CEILING((_xlpm.d-100)/10,1)*運賃マスター!$F$16),IF(_xlpm.vt="1t",IF(_xlpm.d<=100,IFERROR(INDEX(運賃マスター!$J$5:$J$14,MATCH(1,(運賃マスター!$I$5:$I$14>=_xlpm.d)*1,0)),運賃マスター!$J$5),運賃マスター!$J$17+CEILING((_xlpm.d-100)/10,1)*運賃マスター!$J$16),IF(_xlpm.vt="軽",IF(_xlpm.d<=50,IFERROR(INDEX(運賃マスター!$N$5:$N$14,MATCH(1,(運賃マスター!$M$5:$M$14>=_xlpm.d)*1,0)),運賃マスター!$N$5),IF(_xlpm.d<=100,運賃マスター!$N$15+(_xlpm.d-50)*運賃マスター!$N$16,運賃マスター!$N$17+(_xlpm.d-100)*運賃マスター!$N$18)),IF(_xlpm.vt="3tPG",IF(_xlpm.d<=100,IFERROR(INDEX(運賃マスター!$R$5:$R$14,MATCH(1,(運賃マスター!$Q$5:$Q$14>=_xlpm.d)*1,0)),運賃マスター!$R$5),運賃マスター!$R$17+CEILING((_xlpm.d-100)/10,1)*運賃マスター!$R$16),"")))))),""))}
A26: =IF(B26="","",COUNTA($B$5:B26)) | K26: {=IF(OR(H26="",L26=""),"",IFERROR(_xlfn.LET(_xlpm.vt,VLOOKUP(IFERROR(VALUE(LEFT(H26,FIND("＊",H26&"＊")-1)),H26),運賃マスター!$A$22:$B$40,2,FALSE),_xlpm.d,L26,IF(OR(_xlpm.vt="2t",_xlpm.vt="2tユニック",_xlpm.vt="2ｔユニック"),IF(_xlpm.d<=100,IFERROR(INDEX(運賃マスター!$B$5:$B$14,MATCH(1,(運賃マスター!$A$5:$A$14>=_xlpm.d)*1,0)),運賃マスター!$B$5),運賃マスター!$B$17+CEILING((_xlpm.d-100)/10,1)*運賃マスター!$B$16),IF(OR(_xlpm.vt="3t",_xlpm.vt="3tユニック",_xlpm.vt="3ｔユニック"),IF(_xlpm.d<=100,IFERROR(INDEX(運賃マスター!$F$5:$F$14,MATCH(1,(運賃マスター!$E$5:$E$14>=_xlpm.d)*1,0)),運賃マスター!$F$5),運賃マスター!$F$17+CEILING((_xlpm.d-100)/10,1)*運賃マスター!$F$16),IF(_xlpm.vt="1t",IF(_xlpm.d<=100,IFERROR(INDEX(運賃マスター!$J$5:$J$14,MATCH(1,(運賃マスター!$I$5:$I$14>=_xlpm.d)*1,0)),運賃マスター!$J$5),運賃マスター!$J$17+CEILING((_xlpm.d-100)/10,1)*運賃マスター!$J$16),IF(_xlpm.vt="軽",IF(_xlpm.d<=50,IFERROR(INDEX(運賃マスター!$N$5:$N$14,MATCH(1,(運賃マスター!$M$5:$M$14>=_xlpm.d)*1,0)),運賃マスター!$N$5),IF(_xlpm.d<=100,運賃マスター!$N$15+(_xlpm.d-50)*運賃マスター!$N$16,運賃マスター!$N$17+(_xlpm.d-100)*運賃マスター!$N$18)),IF(_xlpm.vt="3tPG",IF(_xlpm.d<=100,IFERROR(INDEX(運賃マスター!$R$5:$R$14,MATCH(1,(運賃マスター!$Q$5:$Q$14>=_xlpm.d)*1,0)),運賃マスター!$R$5),運賃マスター!$R$17+CEILING((_xlpm.d-100)/10,1)*運賃マスター!$R$16),"")))))),""))}
A27: =IF(B27="","",COUNTA($B$5:B27))
A28: =IF(B28="","",COUNTA($B$5:B28)) | K28: {=IF(OR(H28="",L28=""),"",IFERROR(_xlfn.LET(_xlpm.vt,VLOOKUP(IFERROR(VALUE(LEFT(H28,FIND("＊",H28&"＊")-1)),H28),運賃マスター!$A$22:$B$40,2,FALSE),_xlpm.d,L28,IF(OR(_xlpm.vt="2t",_xlpm.vt="2tユニック",_xlpm.vt="2ｔユニック"),IF(_xlpm.d<=100,IFERROR(INDEX(運賃マスター!$B$5:$B$14,MATCH(1,(運賃マスター!$A$5:$A$14>=_xlpm.d)*1,0)),運賃マスター!$B$5),運賃マスター!$B$17+CEILING((_xlpm.d-100)/10,1)*運賃マスター!$B$16),IF(OR(_xlpm.vt="3t",_xlpm.vt="3tユニック",_xlpm.vt="3ｔユニック"),IF(_xlpm.d<=100,IFERROR(INDEX(運賃マスター!$F$5:$F$14,MATCH(1,(運賃マスター!$E$5:$E$14>=_xlpm.d)*1,0)),運賃マスター!$F$5),運賃マスター!$F$17+CEILING((_xlpm.d-100)/10,1)*運賃マスター!$F$16),IF(_xlpm.vt="1t",IF(_xlpm.d<=100,IFERROR(INDEX(運賃マスター!$J$5:$J$14,MATCH(1,(運賃マスター!$I$5:$I$14>=_xlpm.d)*1,0)),運賃マスター!$J$5),運賃マスター!$J$17+CEILING((_xlpm.d-100)/10,1)*運賃マスター!$J$16),IF(_xlpm.vt="軽",IF(_xlpm.d<=50,IFERROR(INDEX(運賃マスター!$N$5:$N$14,MATCH(1,(運賃マスター!$M$5:$M$14>=_xlpm.d)*1,0)),運賃マスター!$N$5),IF(_xlpm.d<=100,運賃マスター!$N$15+(_xlpm.d-50)*運賃マスター!$N$16,運賃マスター!$N$17+(_xlpm.d-100)*運賃マスター!$N$18)),IF(_xlpm.vt="3tPG",IF(_xlpm.d<=100,IFERROR(INDEX(運賃マスター!$R$5:$R$14,MATCH(1,(運賃マスター!$Q$5:$Q$14>=_xlpm.d)*1,0)),運賃マスター!$R$5),運賃マスター!$R$17+CEILING((_xlpm.d-100)/10,1)*運賃マスター!$R$16),"")))))),""))}
A29: =IF(B29="","",COUNTA($B$5:B29))
K30: {=IF(OR(H30="",L30=""),"",IFERROR(_xlfn.LET(_xlpm.vt,VLOOKUP(IFERROR(VALUE(LEFT(H30,FIND("＊",H30&"＊")-1)),H30),運賃マスター!$A$22:$B$40,2,FALSE),_xlpm.d,L30,IF(OR(_xlpm.vt="2t",_xlpm.vt="2tユニック",_xlpm.vt="2ｔユニック"),IF(_xlpm.d<=100,IFERROR(INDEX(運賃マスター!$B$5:$B$14,MATCH(1,(運賃マスター!$A$5:$A$14>=_xlpm.d)*1,0)),運賃マスター!$B$5),運賃マスター!$B$17+CEILING((_xlpm.d-100)/10,1)*運賃マスター!$B$16),IF(OR(_xlpm.vt="3t",_xlpm.vt="3tユニック",_xlpm.vt="3ｔユニック"),IF(_xlpm.d<=100,IFERROR(INDEX(運賃マスター!$F$5:$F$14,MATCH(1,(運賃マスター!$E$5:$E$14>=_xlpm.d)*1,0)),運賃マスター!$F$5),運賃マスター!$F$17+CEILING((_xlpm.d-100)/10,1)*運賃マスター!$F$16),IF(_xlpm.vt="1t",IF(_xlpm.d<=100,IFERROR(INDEX(運賃マスター!$J$5:$J$14,MATCH(1,(運賃マスター!$I$5:$I$14>=_xlpm.d)*1,0)),運賃マスター!$J$5),運賃マスター!$J$17+CEILING((_xlpm.d-100)/10,1)*運賃マスター!$J$16),IF(_xlpm.vt="軽",IF(_xlpm.d<=50,IFERROR(INDEX(運賃マスター!$N$5:$N$14,MATCH(1,(運賃マスター!$M$5:$M$14>=_xlpm.d)*1,0)),運賃マスター!$N$5),IF(_xlpm.d<=100,運賃マスター!$N$15+(_xlpm.d-50)*運賃マスター!$N$16,運賃マスター!$N$17+(_xlpm.d-100)*運賃マスター!$N$18)),IF(_xlpm.vt="3tPG",IF(_xlpm.d<=100,IFERROR(INDEX(運賃マスター!$R$5:$R$14,MATCH(1,(運賃マスター!$Q$5:$Q$14>=_xlpm.d)*1,0)),運賃マスター!$R$5),運賃マスター!$R$17+CEILING((_xlpm.d-100)/10,1)*運賃マスター!$R$16),"")))))),""))}
A31: =IF(B31="","",COUNTA($B$5:B31))
A33: =IF(B33="","",COUNTA($B$5:B33))
A34: =IF(B34="","",COUNTA($B$5:B34))
A35: =IF(B35="","",COUNTA($B$5:B35)) | K35: {=IF(OR(H35="",L35=""),"",IFERROR(_xlfn.LET(_xlpm.vt,VLOOKUP(IFERROR(VALUE(LEFT(H35,FIND("＊",H35&"＊")-1)),H35),運賃マスター!$A$22:$B$40,2,FALSE),_xlpm.d,L35,IF(OR(_xlpm.vt="2t",_xlpm.vt="2tユニック",_xlpm.vt="2ｔユニック"),IF(_xlpm.d<=100,IFERROR(INDEX(運賃マスター!$B$5:$B$14,MATCH(1,(運賃マスター!$A$5:$A$14>=_xlpm.d)*1,0)),運賃マスター!$B$5),運賃マスター!$B$17+CEILING((_xlpm.d-100)/10,1)*運賃マスター!$B$16),IF(OR(_xlpm.vt="3t",_xlpm.vt="3tユニック",_xlpm.vt="3ｔユニック"),IF(_xlpm.d<=100,IFERROR(INDEX(運賃マスター!$F$5:$F$14,MATCH(1,(運賃マスター!$E$5:$E$14>=_xlpm.d)*1,0)),運賃マスター!$F$5),運賃マスター!$F$17+CEILING((_xlpm.d-100)/10,1)*運賃マスター!$F$16),IF(_xlpm.vt="1t",IF(_xlpm.d<=100,IFERROR(INDEX(運賃マスター!$J$5:$J$14,MATCH(1,(運賃マスター!$I$5:$I$14>=_xlpm.d)*1,0)),運賃マスター!$J$5),運賃マスター!$J$17+CEILING((_xlpm.d-100)/10,1)*運賃マスター!$J$16),IF(_xlpm.vt="軽",IF(_xlpm.d<=50,IFERROR(INDEX(運賃マスター!$N$5:$N$14,MATCH(1,(運賃マスター!$M$5:$M$14>=_xlpm.d)*1,0)),運賃マスター!$N$5),IF(_xlpm.d<=100,運賃マスター!$N$15+(_xlpm.d-50)*運賃マスター!$N$16,運賃マスター!$N$17+(_xlpm.d-100)*運賃マスター!$N$18)),IF(_xlpm.vt="3tPG",IF(_xlpm.d<=100,IFERROR(INDEX(運賃マスター!$R$5:$R$14,MATCH(1,(運賃マスター!$Q$5:$Q$14>=_xlpm.d)*1,0)),運賃マスター!$R$5),運賃マスター!$R$17+CEILING((_xlpm.d-100)/10,1)*運賃マスター!$R$16),"")))))),""))}
A37: =IF(B37="","",COUNTA($B$5:B37)) | K37: {=IF(OR(H37="",L37=""),"",IFERROR(_xlfn.LET(_xlpm.vt,VLOOKUP(IFERROR(VALUE(LEFT(H37,FIND("＊",H37&"＊")-1)),H37),運賃マスター!$A$22:$B$40,2,FALSE),_xlpm.d,L37,IF(OR(_xlpm.vt="2t",_xlpm.vt="2tユニック",_xlpm.vt="2ｔユニック"),IF(_xlpm.d<=100,IFERROR(INDEX(運賃マスター!$B$5:$B$14,MATCH(1,(運賃マスター!$A$5:$A$14>=_xlpm.d)*1,0)),運賃マスター!$B$5),運賃マスター!$B$17+CEILING((_xlpm.d-100)/10,1)*運賃マスター!$B$16),IF(OR(_xlpm.vt="3t",_xlpm.vt="3tユニック",_xlpm.vt="3ｔユニック"),IF(_xlpm.d<=100,IFERROR(INDEX(運賃マスター!$F$5:$F$14,MATCH(1,(運賃マスター!$E$5:$E$14>=_xlpm.d)*1,0)),運賃マスター!$F$5),運賃マスター!$F$17+CEILING((_xlpm.d-100)/10,1)*運賃マスター!$F$16),IF(_xlpm.vt="1t",IF(_xlpm.d<=100,IFERROR(INDEX(運賃マスター!$J$5:$J$14,MATCH(1,(運賃マスター!$I$5:$I$14>=_xlpm.d)*1,0)),運賃マスター!$J$5),運賃マスター!$J$17+CEILING((_xlpm.d-100)/10,1)*運賃マスター!$J$16),IF(_xlpm.vt="軽",IF(_xlpm.d<=50,IFERROR(INDEX(運賃マスター!$N$5:$N$14,MATCH(1,(運賃マスター!$M$5:$M$14>=_xlpm.d)*1,0)),運賃マスター!$N$5),IF(_xlpm.d<=100,運賃マスター!$N$15+(_xlpm.d-50)*運賃マスター!$N$16,運賃マスター!$N$17+(_xlpm.d-100)*運賃マスター!$N$18)),IF(_xlpm.vt="3tPG",IF(_xlpm.d<=100,IFERROR(INDEX(運賃マスター!$R$5:$R$14,MATCH(1,(運賃マスター!$Q$5:$Q$14>=_xlpm.d)*1,0)),運賃マスター!$R$5),運賃マスター!$R$17+CEILING((_xlpm.d-100)/10,1)*運賃マスター!$R$16),"")))))),""))}
A38: =IF(B38="","",COUNTA($B$5:B38)) | K38: {=IF(OR(H38="",L38=""),"",IFERROR(_xlfn.LET(_xlpm.vt,VLOOKUP(IFERROR(VALUE(LEFT(H38,FIND("＊",H38&"＊")-1)),H38),運賃マスター!$A$22:$B$40,2,FALSE),_xlpm.d,L38,IF(OR(_xlpm.vt="2t",_xlpm.vt="2tユニック",_xlpm.vt="2ｔユニック"),IF(_xlpm.d<=100,IFERROR(INDEX(運賃マスター!$B$5:$B$14,MATCH(1,(運賃マスター!$A$5:$A$14>=_xlpm.d)*1,0)),運賃マスター!$B$5),運賃マスター!$B$17+CEILING((_xlpm.d-100)/10,1)*運賃マスター!$B$16),IF(OR(_xlpm.vt="3t",_xlpm.vt="3tユニック",_xlpm.vt="3ｔユニック"),IF(_xlpm.d<=100,IFERROR(INDEX(運賃マスター!$F$5:$F$14,MATCH(1,(運賃マスター!$E$5:$E$14>=_xlpm.d)*1,0)),運賃マスター!$F$5),運賃マスター!$F$17+CEILING((_xlpm.d-100)/10,1)*運賃マスター!$F$16),IF(_xlpm.vt="1t",IF(_xlpm.d<=100,IFERROR(INDEX(運賃マスター!$J$5:$J$14,MATCH(1,(運賃マスター!$I$5:$I$14>=_xlpm.d)*1,0)),運賃マスター!$J$5),運賃マスター!$J$17+CEILING((_xlpm.d-100)/10,1)*運賃マスター!$J$16),IF(_xlpm.vt="軽",IF(_xlpm.d<=50,IFERROR(INDEX(運賃マスター!$N$5:$N$14,MATCH(1,(運賃マスター!$M$5:$M$14>=_xlpm.d)*1,0)),運賃マスター!$N$5),IF(_xlpm.d<=100,運賃マスター!$N$15+(_xlpm.d-50)*運賃マスター!$N$16,運賃マスター!$N$17+(_xlpm.d-100)*運賃マスター!$N$18)),IF(_xlpm.vt="3tPG",IF(_xlpm.d<=100,IFERROR(INDEX(運賃マスター!$R$5:$R$14,MATCH(1,(運賃マスター!$Q$5:$Q$14>=_xlpm.d)*1,0)),運賃マスター!$R$5),運賃マスター!$R$17+CEILING((_xlpm.d-100)/10,1)*運賃マスター!$R$16),"")))))),""))}
A39: =IF(B39="","",COUNTA($B$5:B39))
A40: =IF(B40="","",COUNTA($B$5:B40))
A41: =IF(B41="","",COUNTA($B$5:B41)) | K41: {=IF(OR(H41="",L41=""),"",IFERROR(_xlfn.LET(_xlpm.vt,VLOOKUP(IFERROR(VALUE(LEFT(H41,FIND("＊",H41&"＊")-1)),H41),運賃マスター!$A$22:$B$40,2,FALSE),_xlpm.d,L41,IF(OR(_xlpm.vt="2t",_xlpm.vt="2tユニック",_xlpm.vt="2ｔユニック"),IF(_xlpm.d<=100,IFERROR(INDEX(運賃マスター!$B$5:$B$14,MATCH(1,(運賃マスター!$A$5:$A$14>=_xlpm.d)*1,0)),運賃マスター!$B$5),運賃マスター!$B$17+CEILING((_xlpm.d-100)/10,1)*運賃マスター!$B$16),IF(OR(_xlpm.vt="3t",_xlpm.vt="3tユニック",_xlpm.vt="3ｔユニック"),IF(_xlpm.d<=100,IFERROR(INDEX(運賃マスター!$F$5:$F$14,MATCH(1,(運賃マスター!$E$5:$E$14>=_xlpm.d)*1,0)),運賃マスター!$F$5),運賃マスター!$F$17+CEILING((_xlpm.d-100)/10,1)*運賃マスター!$F$16),IF(_xlpm.vt="1t",IF(_xlpm.d<=100,IFERROR(INDEX(運賃マスター!$J$5:$J$14,MATCH(1,(運賃マスター!$I$5:$I$14>=_xlpm.d)*1,0)),運賃マスター!$J$5),運賃マスター!$J$17+CEILING((_xlpm.d-100)/10,1)*運賃マスター!$J$16),IF(_xlpm.vt="軽",IF(_xlpm.d<=50,IFERROR(INDEX(運賃マスター!$N$5:$N$14,MATCH(1,(運賃マスター!$M$5:$M$14>=_xlpm.d)*1,0)),運賃マスター!$N$5),IF(_xlpm.d<=100,運賃マスター!$N$15+(_xlpm.d-50)*運賃マスター!$N$16,運賃マスター!$N$17+(_xlpm.d-100)*運賃マスター!$N$18)),IF(_xlpm.vt="3tPG",IF(_xlpm.d<=100,IFERROR(INDEX(運賃マスター!$R$5:$R$14,MATCH(1,(運賃マスター!$Q$5:$Q$14>=_xlpm.d)*1,0)),運賃マスター!$R$5),運賃マスター!$R$17+CEILING((_xlpm.d-100)/10,1)*運賃マスター!$R$16),"")))))),""))}
D44: 現在待機場所 | E44: 待機予定場所 | H44: 目標距離 | K44: 550
B45: 2(255) | C45: 山岸
...

Sheet 6　2
B2: 46175
B3: 荷主 | C3: 種類 | D3: 積込地 | E3: 積降地 | F3: ユーザー名(搬入/搬出) | G3: 時間 | H3: 号車 | J3: 距離 | K3: 特記事項 | L3: 距離 | M3: 終了地 | N3: 予定時間 | O3: 必要時間 | P3: 件数 | Q3: メモ
A5: =IF(B5="","",COUNTA($B$5:B5)) | I5: =IFERROR(_xlfn.XLOOKUP(H5,案件・ドライバー一覧!$L$3:$L$17,案件・ドライバー一覧!$M$3:$M$17,""),"") | K5: {=IF(OR(H5="",L5=""),"",IFERROR(_xlfn.LET(_xlpm.vt,VLOOKUP(IFERROR(VALUE(LEFT(H5,FIND("＊",H5&"＊")-1)),H5),運賃マスター!$A$22:$B$40,2,FALSE),_xlpm.d,L5,IF(OR(_xlpm.vt="2t",_xlpm.vt="2tユニック",_xlpm.vt="2ｔユニック"),IF(_xlpm.d<=100,IFERROR(INDEX(運賃マスター!$B$5:$B$14,MATCH(1,(運賃マスター!$A$5:$A$14>=_xlpm.d)*1,0)),運賃マスター!$B$5),運賃マスター!$B$17+CEILING((_xlpm.d-100)/10,1)*運賃マスター!$B$16),IF(OR(_xlpm.vt="3t",_xlpm.vt="3tユニック",_xlpm.vt="3ｔユニック"),IF(_xlpm.d<=100,IFERROR(INDEX(運賃マスター!$F$5:$F$14,MATCH(1,(運賃マスター!$E$5:$E$14>=_xlpm.d)*1,0)),運賃マスター!$F$5),運賃マスター!$F$17+CEILING((_xlpm.d-100)/10,1)*運賃マスター!$F$16),IF(_xlpm.vt="1t",IF(_xlpm.d<=100,IFERROR(INDEX(運賃マスター!$J$5:$J$14,MATCH(1,(運賃マスター!$I$5:$I$14>=_xlpm.d)*1,0)),運賃マスター!$J$5),運賃マスター!$J$17+CEILING((_xlpm.d-100)/10,1)*運賃マスター!$J$16),IF(_xlpm.vt="軽",IF(_xlpm.d<=50,IFERROR(INDEX(運賃マスター!$N$5:$N$14,MATCH(1,(運賃マスター!$M$5:$M$14>=_xlpm.d)*1,0)),運賃マスター!$N$5),IF(_xlpm.d<=100,運賃マスター!$N$15+(_xlpm.d-50)*運賃マスター!$N$16,運賃マスター!$N$17+(_xlpm.d-100)*運賃マスター!$N$18)),IF(_xlpm.vt="3tPG",IF(_xlpm.d<=100,IFERROR(INDEX(運賃マスター!$R$5:$R$14,MATCH(1,(運賃マスター!$Q$5:$Q$14>=_xlpm.d)*1,0)),運賃マスター!$R$5),運賃マスター!$R$17+CEILING((_xlpm.d-100)/10,1)*運賃マスター!$R$16),"")))))),""))}
A6: =IF(B6="","",COUNTA($B$5:B6)) | I6: =IFERROR(_xlfn.XLOOKUP(H6,案件・ドライバー一覧!$L$3:$L$17,案件・ドライバー一覧!$M$3:$M$17,""),"") | K6: {=IF(OR(H6="",L6=""),"",IFERROR(_xlfn.LET(_xlpm.vt,VLOOKUP(IFERROR(VALUE(LEFT(H6,FIND("＊",H6&"＊")-1)),H6),運賃マスター!$A$22:$B$40,2,FALSE),_xlpm.d,L6,IF(OR(_xlpm.vt="2t",_xlpm.vt="2tユニック",_xlpm.vt="2ｔユニック"),IF(_xlpm.d<=100,IFERROR(INDEX(運賃マスター!$B$5:$B$14,MATCH(1,(運賃マスター!$A$5:$A$14>=_xlpm.d)*1,0)),運賃マスター!$B$5),運賃マスター!$B$17+CEILING((_xlpm.d-100)/10,1)*運賃マスター!$B$16),IF(OR(_xlpm.vt="3t",_xlpm.vt="3tユニック",_xlpm.vt="3ｔユニック"),IF(_xlpm.d<=100,IFERROR(INDEX(運賃マスター!$F$5:$F$14,MATCH(1,(運賃マスター!$E$5:$E$14>=_xlpm.d)*1,0)),運賃マスター!$F$5),運賃マスター!$F$17+CEILING((_xlpm.d-100)/10,1)*運賃マスター!$F$16),IF(_xlpm.vt="1t",IF(_xlpm.d<=100,IFERROR(INDEX(運賃マスター!$J$5:$J$14,MATCH(1,(運賃マスター!$I$5:$I$14>=_xlpm.d)*1,0)),運賃マスター!$J$5),運賃マスター!$J$17+CEILING((_xlpm.d-100)/10,1)*運賃マスター!$J$16),IF(_xlpm.vt="軽",IF(_xlpm.d<=50,IFERROR(INDEX(運賃マスター!$N$5:$N$14,MATCH(1,(運賃マスター!$M$5:$M$14>=_xlpm.d)*1,0)),運賃マスター!$N$5),IF(_xlpm.d<=100,運賃マスター!$N$15+(_xlpm.d-50)*運賃マスター!$N$16,運賃マスター!$N$17+(_xlpm.d-100)*運賃マスター!$N$18)),IF(_xlpm.vt="3tPG",IF(_xlpm.d<=100,IFERROR(INDEX(運賃マスター!$R$5:$R$14,MATCH(1,(運賃マスター!$Q$5:$Q$14>=_xlpm.d)*1,0)),運賃マスター!$R$5),運賃マスター!$R$17+CEILING((_xlpm.d-100)/10,1)*運賃マスター!$R$16),"")))))),""))}
A7: =IF(B7="","",COUNTA($B$5:B7)) | I7: =IFERROR(_xlfn.XLOOKUP(H7,案件・ドライバー一覧!$L$3:$L$17,案件・ドライバー一覧!$M$3:$M$17,""),"") | K7: {=IF(OR(H7="",L7=""),"",IFERROR(_xlfn.LET(_xlpm.vt,VLOOKUP(IFERROR(VALUE(LEFT(H7,FIND("＊",H7&"＊")-1)),H7),運賃マスター!$A$22:$B$40,2,FALSE),_xlpm.d,L7,IF(OR(_xlpm.vt="2t",_xlpm.vt="2tユニック",_xlpm.vt="2ｔユニック"),IF(_xlpm.d<=100,IFERROR(INDEX(運賃マスター!$B$5:$B$14,MATCH(1,(運賃マスター!$A$5:$A$14>=_xlpm.d)*1,0)),運賃マスター!$B$5),運賃マスター!$B$17+CEILING((_xlpm.d-100)/10,1)*運賃マスター!$B$16),IF(OR(_xlpm.vt="3t",_xlpm.vt="3tユニック",_xlpm.vt="3ｔユニック"),IF(_xlpm.d<=100,IFERROR(INDEX(運賃マスター!$F$5:$F$14,MATCH(1,(運賃マスター!$E$5:$E$14>=_xlpm.d)*1,0)),運賃マスター!$F$5),運賃マスター!$F$17+CEILING((_xlpm.d-100)/10,1)*運賃マスター!$F$16),IF(_xlpm.vt="1t",IF(_xlpm.d<=100,IFERROR(INDEX(運賃マスター!$J$5:$J$14,MATCH(1,(運賃マスター!$I$5:$I$14>=_xlpm.d)*1,0)),運賃マスター!$J$5),運賃マスター!$J$17+CEILING((_xlpm.d-100)/10,1)*運賃マスター!$J$16),IF(_xlpm.vt="軽",IF(_xlpm.d<=50,IFERROR(INDEX(運賃マスター!$N$5:$N$14,MATCH(1,(運賃マスター!$M$5:$M$14>=_xlpm.d)*1,0)),運賃マスター!$N$5),IF(_xlpm.d<=100,運賃マスター!$N$15+(_xlpm.d-50)*運賃マスター!$N$16,運賃マスター!$N$17+(_xlpm.d-100)*運賃マスター!$N$18)),IF(_xlpm.vt="3tPG",IF(_xlpm.d<=100,IFERROR(INDEX(運賃マスター!$R$5:$R$14,MATCH(1,(運賃マスター!$Q$5:$Q$14>=_xlpm.d)*1,0)),運賃マスター!$R$5),運賃マスター!$R$17+CEILING((_xlpm.d-100)/10,1)*運賃マスター!$R$16),"")))))),""))}
A8: =IF(B8="","",COUNTA($B$5:B8)) | K8: {=IF(OR(H8="",L8=""),"",IFERROR(_xlfn.LET(_xlpm.vt,VLOOKUP(IFERROR(VALUE(LEFT(H8,FIND("＊",H8&"＊")-1)),H8),運賃マスター!$A$22:$B$40,2,FALSE),_xlpm.d,L8,IF(OR(_xlpm.vt="2t",_xlpm.vt="2tユニック",_xlpm.vt="2ｔユニック"),IF(_xlpm.d<=100,IFERROR(INDEX(運賃マスター!$B$5:$B$14,MATCH(1,(運賃マスター!$A$5:$A$14>=_xlpm.d)*1,0)),運賃マスター!$B$5),運賃マスター!$B$17+CEILING((_xlpm.d-100)/10,1)*運賃マスター!$B$16),IF(OR(_xlpm.vt="3t",_xlpm.vt="3tユニック",_xlpm.vt="3ｔユニック"),IF(_xlpm.d<=100,IFERROR(INDEX(運賃マスター!$F$5:$F$14,MATCH(1,(運賃マスター!$E$5:$E$14>=_xlpm.d)*1,0)),運賃マスター!$F$5),運賃マスター!$F$17+CEILING((_xlpm.d-100)/10,1)*運賃マスター!$F$16),IF(_xlpm.vt="1t",IF(_xlpm.d<=100,IFERROR(INDEX(運賃マスター!$J$5:$J$14,MATCH(1,(運賃マスター!$I$5:$I$14>=_xlpm.d)*1,0)),運賃マスター!$J$5),運賃マスター!$J$17+CEILING((_xlpm.d-100)/10,1)*運賃マスター!$J$16),IF(_xlpm.vt="軽",IF(_xlpm.d<=50,IFERROR(INDEX(運賃マスター!$N$5:$N$14,MATCH(1,(運賃マスター!$M$5:$M$14>=_xlpm.d)*1,0)),運賃マスター!$N$5),IF(_xlpm.d<=100,運賃マスター!$N$15+(_xlpm.d-50)*運賃マスター!$N$16,運賃マスター!$N$17+(_xlpm.d-100)*運賃マスター!$N$18)),IF(_xlpm.vt="3tPG",IF(_xlpm.d<=100,IFERROR(INDEX(運賃マスター!$R$5:$R$14,MATCH(1,(運賃マスター!$Q$5:$Q$14>=_xlpm.d)*1,0)),運賃マスター!$R$5),運賃マスター!$R$17+CEILING((_xlpm.d-100)/10,1)*運賃マスター!$R$16),"")))))),""))}
A9: =IF(B9="","",COUNTA($B$5:B9)) | K9: {=IF(OR(H9="",L9=""),"",IFERROR(_xlfn.LET(_xlpm.vt,VLOOKUP(IFERROR(VALUE(LEFT(H9,FIND("＊",H9&"＊")-1)),H9),運賃マスター!$A$22:$B$40,2,FALSE),_xlpm.d,L9,IF(OR(_xlpm.vt="2t",_xlpm.vt="2tユニック",_xlpm.vt="2ｔユニック"),IF(_xlpm.d<=100,IFERROR(INDEX(運賃マスター!$B$5:$B$14,MATCH(1,(運賃マスター!$A$5:$A$14>=_xlpm.d)*1,0)),運賃マスター!$B$5),運賃マスター!$B$17+CEILING((_xlpm.d-100)/10,1)*運賃マスター!$B$16),IF(OR(_xlpm.vt="3t",_xlpm.vt="3tユニック",_xlpm.vt="3ｔユニック"),IF(_xlpm.d<=100,IFERROR(INDEX(運賃マスター!$F$5:$F$14,MATCH(1,(運賃マスター!$E$5:$E$14>=_xlpm.d)*1,0)),運賃マスター!$F$5),運賃マスター!$F$17+CEILING((_xlpm.d-100)/10,1)*運賃マスター!$F$16),IF(_xlpm.vt="1t",IF(_xlpm.d<=100,IFERROR(INDEX(運賃マスター!$J$5:$J$14,MATCH(1,(運賃マスター!$I$5:$I$14>=_xlpm.d)*1,0)),運賃マスター!$J$5),運賃マスター!$J$17+CEILING((_xlpm.d-100)/10,1)*運賃マスター!$J$16),IF(_xlpm.vt="軽",IF(_xlpm.d<=50,IFERROR(INDEX(運賃マスター!$N$5:$N$14,MATCH(1,(運賃マスター!$M$5:$M$14>=_xlpm.d)*1,0)),運賃マスター!$N$5),IF(_xlpm.d<=100,運賃マスター!$N$15+(_xlpm.d-50)*運賃マスター!$N$16,運賃マスター!$N$17+(_xlpm.d-100)*運賃マスター!$N$18)),IF(_xlpm.vt="3tPG",IF(_xlpm.d<=100,IFERROR(INDEX(運賃マスター!$R$5:$R$14,MATCH(1,(運賃マスター!$Q$5:$Q$14>=_xlpm.d)*1,0)),運賃マスター!$R$5),運賃マスター!$R$17+CEILING((_xlpm.d-100)/10,1)*運賃マスター!$R$16),"")))))),""))}
A10: =IF(B10="","",COUNTA($B$5:B10)) | K10: {=IF(OR(H10="",L10=""),"",IFERROR(_xlfn.LET(_xlpm.vt,VLOOKUP(IFERROR(VALUE(LEFT(H10,FIND("＊",H10&"＊")-1)),H10),運賃マスター!$A$22:$B$40,2,FALSE),_xlpm.d,L10,IF(OR(_xlpm.vt="2t",_xlpm.vt="2tユニック",_xlpm.vt="2ｔユニック"),IF(_xlpm.d<=100,IFERROR(INDEX(運賃マスター!$B$5:$B$14,MATCH(1,(運賃マスター!$A$5:$A$14>=_xlpm.d)*1,0)),運賃マスター!$B$5),運賃マスター!$B$17+CEILING((_xlpm.d-100)/10,1)*運賃マスター!$B$16),IF(OR(_xlpm.vt="3t",_xlpm.vt="3tユニック",_xlpm.vt="3ｔユニック"),IF(_xlpm.d<=100,IFERROR(INDEX(運賃マスター!$F$5:$F$14,MATCH(1,(運賃マスター!$E$5:$E$14>=_xlpm.d)*1,0)),運賃マスター!$F$5),運賃マスター!$F$17+CEILING((_xlpm.d-100)/10,1)*運賃マスター!$F$16),IF(_xlpm.vt="1t",IF(_xlpm.d<=100,IFERROR(INDEX(運賃マスター!$J$5:$J$14,MATCH(1,(運賃マスター!$I$5:$I$14>=_xlpm.d)*1,0)),運賃マスター!$J$5),運賃マスター!$J$17+CEILING((_xlpm.d-100)/10,1)*運賃マスター!$J$16),IF(_xlpm.vt="軽",IF(_xlpm.d<=50,IFERROR(INDEX(運賃マスター!$N$5:$N$14,MATCH(1,(運賃マスター!$M$5:$M$14>=_xlpm.d)*1,0)),運賃マスター!$N$5),IF(_xlpm.d<=100,運賃マスター!$N$15+(_xlpm.d-50)*運賃マスター!$N$16,運賃マスター!$N$17+(_xlpm.d-100)*運賃マスター!$N$18)),IF(_xlpm.vt="3tPG",IF(_xlpm.d<=100,IFERROR(INDEX(運賃マスター!$R$5:$R$14,MATCH(1,(運賃マスター!$Q$5:$Q$14>=_xlpm.d)*1,0)),運賃マスター!$R$5),運賃マスター!$R$17+CEILING((_xlpm.d-100)/10,1)*運賃マスター!$R$16),"")))))),""))}
